Workbook

Sheet HU-MOD-2_Explanations
A1: HU-MOD-2
A3: List of parameters
A4: Column No. | B4: Var. Name EN | C4: Type | D4: Unit | E4: Input requirement | F4: Data base / calculation | G4: Explanations
A5: 1 | B5: ID_1 | C5: Not specified | D5: None | E5: optional | F5: Input data | G5: Unlimited
A6: 2 | B6: ID_2 | C6: Not specified | D6: None | E6: optional | F6: Input data | G6: Unlimited
A7: 3 | B7: ID_3 | C7: Not specified | D7: None | E7: optional | F7: Input data | G7: Unlimited
A8: 4 | B8: ID_4 | C8: Not specified | D8: None | E8: optional | F8: Input data | G8: Unlimited
A9: 5 | B9: SITECN | C9: Numeric | D9: Quotient | E9: mandatory | F9: Input data | G9: Mean topsoil CN ratio
A10: 6 | B10: PV | C10: Numeric | D10: Factor | E10: mandatory | F10: Input data | G10: Pore volume in 0-90 cm soil depth as decial share (0…1). Default 0,4.
A11: 7 | B11: PRECIP | C11: Numeric | D11: mm*a-1 | E11: mandatory | F11: Input data | G11: Mean annual precipitation.
A12: 8 | B12: WINTERPRECIP | C12: Numeric | D12: Factor | E12: mandatory | F12: Input data | G12: Share of precipitation over winter (NOV-MAR)
A13: 9 | B13: NADEP | C13: Numeric | D13: kg N ha-1 | E13: mandatory | F13: Input data | G13: Atmospheric N Deposition kg/ha/a. Default 20
A14: 10 | B14: Year | C14: Numeric | D14: Number | E14: mandatory | F14: Input data | G14: Year (calendrical or 1,2,3,...)
A15: 11 | B15: Cut | C15: Numeric | D15: Number | F15: Input data | G15: Cut Number (if applicable). Every cut is treated as an own crop entry in the model structure.
A16: 12 | B16: Crop | C16: Text | D16: None | E16: optional | F16: Input data | G16: Crop name
A17: 13 | B17: CROP_ID | C17: Numeric | D17: ID | E17: mandatory | F17: Input data | G17: According to sheet HU-MOD-2-Parameters_Crop.
A18: 14 | B18: LEGSHARE | C18: Numeric | D18: decimal rate | E18: mandatory | F18: Input data | G18: Legume share in a mixed crop or pure legume crop (0…1).
A19: 15 | B19: MINFTLZ_AMNT | C19: Numeric | D19: kg N ha-1 | E19: optional | F19: Input data | G19: Mineral N fertilization (artificial non-organic fertilizer).
A20: 16 | B20: ORGFTLZ_1 | C20: Text | D20: None | E20: optional | F20: Input data | G20: Organic fertilizer no. 1
A21: 17 | B21: ORGFTLZ_1_ID | C21: Numeric | D21: ID | E21: optional | F21: Input data | G21: According to sheet "HU-MOD-2-Parameters_FTLZ"
A22: 18 | B22: ORGFTLZ_1_AMNT | C22: Numeric | D22: MG FM ha-1 | E22: optional | F22: Input data | G22: Amount of Organic fertilizer 1
A23: 19 | B23: ORGFTLZ_1_APPLIC | C23: Numeric | D23: ID | E23: optional | F23: Input data | G23: Application situation of organic fertilizer 1: 1=in period of low N uptake, 2=in period of high N uptake (directly before cover crops, application in growing crop)
A24: 20 | B24: ORGFTLZ_2 | C24: Text | D24: None | E24: optional | F24: Input data | G24: Organic fertilizer no. 2
A25: 21 | B25: ORGFTLZ_2_ID | C25: Numeric | D25: ID | E25: optional | F25: Input data | G25: According to sheet "HU-MOD-2-Parameters_FTLZ"
A26: 22 | B26: ORGFTLZ_2_AMNT | C26: Numeric | D26: MG FM ha-1 | E26: optional | F26: Input data | G26: Amount of Organic fertilizer 2
A27: 23 | B27: ORGFTLZ_2_APPLIC | C27: Numeric | D27: ID | E27: optional | F27: Input data | G27: Application situation of organic fertilizer 2: 1=in period of low N uptake, 2=in period of high N uptake (directly before cover crops, application in growing crop)
... A30: 26 | B30: STR_AMNT | C30: Numeric | D30: MG FM ha-1 | E30: optional | F30: Input data | G30: Straw amount
B31: STR_APPLIC | C31: Numeric | F31: Input data | G31: Application situation of straw: 1=in period of low N uptake, 2=in period of high N uptake (directly before cover crops, application in growing crop)
A32: 28 | B32: MP_AMNT | C32: Numeric | D32: MG FM ha-1 | E32: mandatory | F32: Input data | G32: Main product amount
A33: 29 | B33: GREENMAN? | C33: Y/N | D33: Y/N | E33: optional | F33: Input data | G33: Y=crop not harvested (green manure for succeeding crops), N=crop harvested (Main product or full crop)
A34: 30 | B34: SP_AMNT | C34: Numeric | D34: MG FM ha-1 | E34: optional | F34: Input data | G34: Side product (straw) amount
A35: 31 | B35: STRLEFT? | C35: Y/N | D35: Y/N | E35: optional | F35: Input data | G35: Y=side product (straw) not harvested (straw fertilization for succeeding crops), N=side product (straw) harvested
A36: 32 | B36: LIT_AMNT | C36: Numeric | D36: MG FM ha-1 | E36: optional | F36: Input data | G36: Litterfall amount
A37: 33 | B37: STB_AMNT | C37: Numeric | D37: MG FM ha-1 | E37: optional | F37: Input data | G37: Stubble amount
A38: 34 | B38: RTS_AMNT | C38: Numeric | D38: MG FM ha-1 | E38: optional | F38: Input data | G38: Root biomass (amount)
A39: 35 | B39: DMCONT_MP | C39: Numeric | D39: Factor | E39: optional | F39: Input data | G39: Dry matter content of main product
A40: 36 | B40: CCONT_MP | C40: Numeric | D40: Factor | E40: optional | F40: Input data | G40: C content in dry matter of main product
A41: 37 | B41: NCONT_MP | C41: Numeric | D41: Factor | E41: optional | F41: Input data | G41: N content in dry matter of main product
A42: 38 | B42: DMCONT_SP | C42: Numeric | D42: Factor | E42: optional | F42: Input data | G42: Dry matter content of side product
A43: 39 | B43: CCONT_SP | C43: Numeric | D43: Factor | E43: optional | F43: Input data | G43: C content in dry matter of side product
...

Sheet HU-MOD-2_Input data
A1: ID_1 | B1: ID_2 | C1: ID_3 | D1: ID_4 | E1: SITECN | F1: PV | G1: PRECIP | H1: WINTERPRECIP | I1: NADEP | J1: Year | K1: Cut | L1: Crop | M1: CROP_ID | N1: LEGSHARE | O1: MINFTLZ_AMNT | P1: ORGFTLZ_1 | Q1: ORGFTLZ_1_ID | R1: ORGFTLZ_1_AMNT | S1: ORGFTLZ_1_APPLIC | T1: ORGFTLZ_2 | U1: ORGFTLZ_2_ID | V1: ORGFTLZ_2_AMNT | W1: ORGFTLZ_2_APPLIC | X1: GREENMAN_AMNT | Y1: GREENMAN_APPLIC | Z1: STR_AMNT | AA1: STR_APPLIC | AB1: MP_AMNT | AC1: GREENMAN? | AD1: SP_AMNT | AE1: STRLEFT? | AF1: LIT_AMNT | AG1: STB_AMNT | AH1: RTS_AMNT | AI1: DMCONT_MP | AJ1: CCONT_MP | AK1: NCONT_MP | AL1: DMCONT_SP | AM1: CCONT_SP | AN1: NCONT_SP | AO1: DMCONT_LIT | AP1: CCONTLIT | AQ1: NCONT_LIT | AR1: DMCONT_STB | AS1: CCONT_STB | AT1: NCONT_STB | AU1: DMCONT_RTS | AV1: CCONT_RTS | AW1: NCONT_RTS | AX1: DMCONT_FTLZ_1 | AY1: CCONT_FTLZ_1 | AZ1: NCONT_FTLZ_1 | BA1: DMCONT_FTLZ_2 | BB1: CCONT_FTLZ_2 | BC1: NCONT_FTLZ_2 | BG1: BNF | BH1: NNYR | BI1: SOMLOSS | BJ1: SOMSUP | BK1: SOMBALC | BL1: SOMBALN | BM1: SOMBALC_Y | BN1: SOMBALN_Y | BO1: NPB | BP1: NBNF | BQ1: NFTLZ | BR1: NDEP | BS1: NNYR | BT1: CSUP_HR | BU1: CSUP_FTLZ | BV1: NSUP_HR | BW1: NSUP_FTLZ | BY1: DMCONTMP | BZ1: CCONTMP | CA1: NCONTMP | CB1: SP_AMNT | CC1: DMCONTSP | CD1: CCONT_SP | CE1: NCONT_SP | CF1: LIT_AMNT | CG1: DMCONTLIT | CH1: CCONTLIT | CI1: NCONTLIT | CJ1: STB_AMNT | CK1: DMCONTSTB | CL1: CCONT_STB | CM1: NCONT_STB | CN1: RTS_AMNT | CO1: DMCONTRTS | CP1: CCONT_RTS | CQ1: NCONT_RTS | CR1: DMCONTFTLZ_1 | CS1: CCONTFTLZ_1 | CT1: NCONTFTLZ_1 | CU1: FTLZNAV_1 | CV1: DMCONTFTLZ_2 | CW1: CCONTFTLZ_2 | CX1: NCONTFTLZ_2 | CY1: FTLZNAV_2 | CZ1: GREENMAN_AMNT | DA1: FTLZNAV_GREENMAN | DB1: STR_AMNT | DC1: FTLZNAV_STR | DE1: LEGSHARE | DF1: BNF | DH1: FTLZNUE_direct | DI1: FTLZNUE_LOWUPT | DJ1: NFTLZMAX
A2: COPY COLUMNS Y…AK and BA…BT of this line to every line with a data record! | AE2: N | BI2: =E2*(IF(0<BO2-BP2-BQ2-BR2,BO2-BP2-BQ2-BR2,0)-BS2) -> #DIV/0! | BJ2: =IF((BV2+BW2)*E2<BT2+BU2,(BV2+BW2)*E2,BT2+BU2) -> #VALUE! | BK2: =BJ2-BI2 -> #VALUE! | BL2: =BK2/E2 -> #VALUE! | BM2: =IF($J3=$J2,BK3+BK2,IF($J1=$J2,"",BK2)) -> #VALUE! | BN2: =IF($J3=$J2,BL3+BL2,IF($J1=$J2,"",BL2)) -> #VALUE! | BO2: =1000*(AB2*BY2*CA2+CB2*CC2*CE2+CF2*CG2*CI2+CJ2*CK2*CM2+CN2*CO2*CQ2) -> 0 | BP2: =IF(0<BO2*DE2*DF2-BQ2-BR2,BO2*DE2*DF2-BQ2-BR2,0) -> #DIV/0! | BQ2: =IF(BO2*DJ2>CU2+CY2+DA2+DC2+O2,CU2+CY2+DA2+DC2+O2,BO2*DJ2) -> 0 | BR2: =I2*DI2 -> #DIV/0! | BS2: =DG2*(1-DI2) -> #DIV/0! | BT2: =1000*(CF2*CG2*CH2+CJ2*CK2*CL2+CN2*CO2*CP2) -> 0 | BU2: =1000*(R2*CR2*CS2+V2*CV2*CW2+CZ2*BY1*BZ1+DB2*CC1*CD1) -> #VALUE! | BV2: =1000*(CF2*CG2*CI2+CJ2*CK2*CM2+CN2*CO2*CQ2) -> 0 | BW2: =1000*(IF(R2=0,0,R2*CR2*CT2*(1-1.6674*POWER(CS2/CT2,-0.768)))+IF(V2=0,0,V2*CV2*CX2*(1-1.6674*POWER(CW2/CX2,-0.768)))+IF(CZ2=0,0,CZ2*BY1*CA1*(1-1.6674*POWER(BZ2/CA2,-0.768)))+IF(DB2=0,0,DB2*CC1*CE1*(1-1.6674*POWER(CD1/CE1,-0.768)))) -> 0 | BY2: =IF(AI2="",VLOOKUP($M2,'HU-MOD-2-Parameters_CROP'!$A$4:$AE$151,5,),AI2) -> 0 | BZ2: =IF(AJ2="",VLOOKUP($M2,'HU-MOD-2-Parameters_CROP'!$A$4:$AE$151,6,),AJ2) -> 0 | CA2: =IF(AK2="",VLOOKUP($M2,'HU-MOD-2-Parameters_CROP'!$A$4:$AE$151,7,),AK2) -> 0 | CB2: =IF(AD2="",$AB2*VLOOKUP($M2,'HU-MOD-2-Parameters_CROP'!$A$4:$AE$201,8,),AD2) -> 0 | CC2: =IF(AL2="",VLOOKUP($M2,'HU-MOD-2-Parameters_CROP'!$A$4:$AE$151,9,),AL2) -> 0 | CD2: =IF(AM2="",VLOOKUP($M2,'HU-MOD-2-Parameters_CROP'!$A$4:$AE$151,10,),AM2) -> 0 | CE2: =IF(AN2="",VLOOKUP($M2,'HU-MOD-2-Parameters_CROP'!$A$4:$AE$151,11,),AN2) -> 0 | CF2: =IF(AF2="",$AB2*VLOOKUP($M2,'HU-MOD-2-Parameters_CROP'!$A$4:$AE$201,12,),AF2) -> 0 | CG2: =IF(AO2="",VLOOKUP($M2,'HU-MOD-2-Parameters_CROP'!$A$4:$AE$151,13,),AO2) -> 0 | CH2: =IF(AP2="",VLOOKUP($M2,'HU-MOD-2-Parameters_CROP'!$A$4:$AE$151,14,),AP2) -> 0 | CI2: =IF(AQ2="",VLOOKUP($M2,'HU-MOD-2-Parameters_CROP'!$A$4:$AE$151,15,),AQ2) -> 0 | CJ2: =IF(AG2="",$AB2*VLOOKUP($M2,'HU-MOD-2-Parameters_CROP'!$A$4:$AE$201,16,),AG2) -> 0 | CK2: =IF(AR2="",VLOOKUP($M2,'HU-MOD-2-Parameters_CROP'!$A$4:$AE$151,17,),AR2) -> 0 | CL2: =IF(AS2="",VLOOKUP($M2,'HU-MOD-2-Parameters_CROP'!$A$4:$AE$151,18,),AS2) -> 0 | CM2: =IF(AT2="",VLOOKUP($M2,'HU-MOD-2-Parameters_CROP'!$A$4:$AE$151,19,),AT2) -> 0 | CN2: =IF(AH2="",$AB2*BY2*VLOOKUP($M2,'HU-MOD-2-Parameters_CROP'!$A$4:$AE$201,20,),AH2) -> 0 | CO2: =IF(AU2="",VLOOKUP($M2,'HU-MOD-2-Parameters_CROP'!$A$4:$AE$151,21,),AU2) -> 0 | CP2: =IF(AV2="",VLOOKUP($M2,'HU-MOD-2-Parameters_CROP'!$A$4:$AE$151,22,),AV2) -> 0 | CQ2: =IF(AW2="",VLOOKUP($M2,'HU-MOD-2-Parameters_CROP'!$A$4:$AE$151,23,),AW2) -> 0 | CR2: =IF(AX2="",VLOOKUP($Q2,'HU-MOD-2-Parameters_FTLZ'!$A$4:$I$109,5,),AX2) -> 0 | CS2: =IF(AY2="",VLOOKUP($Q2,'HU-MOD-2-Parameters_FTLZ'!$A$4:$I$109,6,),AY2) -> 0 | CT2: =IF(AZ2="",VLOOKUP($Q2,'HU-MOD-2-Parameters_FTLZ'!$A$4:$I$109,7,),AZ2) -> 0 | CU2: =IF(CR2=0,0,IF(S2=1,1000*R2*CR2*CT2*(1.6674*POWER(CS2/CT2,-0.768))*DI2,1000*R2*CR2*CT2*(1.6674*POWER(CS2/CT2,-0.768))*DH2)) -> 0 | CV2: =IF(BA2="",VLOOKUP($U2,'HU-MOD-2-Parameters_FTLZ'!$A$4:$I$109,5,),BA2) -> 0 | CW2: =IF(BB2="",VLOOKUP($U2,'HU-MOD-2-Parameters_FTLZ'!$A$4:$I$109,6,),BB2) -> 0 | CX2: =IF(BC2="",VLOOKUP($U2,'HU-MOD-2-Parameters_FTLZ'!$A$4:$I$109,7,),BC2) -> 0 | CY2: =IF(CV2=0,0,IF(W2=1,1000*V2*CV2*CX2*(1.6674*POWER(CW2/CX2,-0.768))*DM2,1000*V2*CV2*CX2*(1.6674*POWER(CW2/CX2,-0.768))*DL2)) -> 0 | CZ2: =IF(X2="",IF(AC1="Y",AB1,0),X2) -> 0 | DA2: =IF(AC1="Y",IF(Y2=1,1000*CZ2*BY1*CA1*1.6674*POWER(BZ1/CA1,-0.768)*DI2,1000*CZ2*BY1*CA1*1.6674*POWER(BZ1/CA1,-0.768)*DH2),0) -> 0 | DB2: =IF(Z2="",IF(AE1="Y",CB1,0),Z2) -> 0 | DC2: =IF(AE1="Y",IF(AB2=1,1000*DB2*CC1*CE1*1.6674*POWER(CD1/CE1,-0.768)*DI2,1000*DB2*CC1*CE1*1.6674*POWER(CD1/CE1,-0.768)*DH2),0) -> 0 | DE2: =IF(N2="",VLOOKUP(M2,'HU-MOD-2-Parameters_CROP'!$A$4:$AE$151,24,),N2) -> 0 | DF2: =IF(BG2="",VLOOKUP(M2,'HU-MOD-2-Parameters_CROP'!$A$4:$AE$151,25,),BG2) -> 0 | DG2: =IF(BH2="",VLOOKUP(M2,'HU-MOD-2-Parameters_CROP'!$A$4:$AE$151,26,),BH2) -> 0 | DH2: 1 | DI2: =1-POWER(((G2/10*H2)/(G2/10*H2+F2)),0.5*90) -> #DIV/0! | DJ2: 0.6
A3: Gemischtbetrieb | B3: Öko | E3: 10 | F3: 0.4 | G3: 650 | H3: 0.5 | I3: 20 | J3: 1 | L3: Kleegras | M3: 1050 | N3: 0.9 | O3: 0 | AB3: 60 | AC3: N | AE3: N | BI3: =E3*(IF(0<BO3-BP3-BQ3-BR3,BO3-BP3-BQ3-BR3,0)-BS3) -> 1381.8 | BJ3: =IF((BV3+BW3)*E3<BT3+BU3,(BV3+BW3)*E3,BT3+BU3) -> 2448 | BK3: =BJ3-BI3 -> 1066.2 | BL3: =BK3/E3 -> 106.62 | BM3: =IF($J4=$J3,BK4+BK3,IF($J2=$J3,"",BK3)) -> 1066.2 | BN3: =IF($J4=$J3,BL4+BL3,IF($J2=$J3,"",BL3)) -> 106.62 | BO3: =1000*(AB3*BY3*CA3+CB3*CC3*CE3+CF3*CG3*CI3+CJ3*CK3*CM3+CN3*CO3*CQ3) -> 588 | BP3: =IF(0<BO3*DE3*DF3-BQ3-BR3,BO3*DE3*DF3-BQ3-BR3,0) -> 441.35363 | BQ3: =IF(BO3*DJ3>CU3+CY3+DA3+DC3+O3,CU3+CY3+DA3+DC3+O3,BO3*DJ3) -> 0 | BR3: =I3*DI3 -> 8.4663749 | BS3: =DG3*(1-DI3) -> 0 | BT3: =1000*(CF3*CG3*CH3+CJ3*CK3*CL3+CN3*CO3*CP3) -> 4800 | BU3: =1000*(R3*CR3*CS3+V3*CV3*CW3+CZ3*BY2*BZ2+DB3*CC2*CD2) -> 0 | BV3: =1000*(CF3*CG3*CI3+CJ3*CK3*CM3+CN3*CO3*CQ3) -> 244.8 | BW3: =1000*(IF(R3=0,0,R3*CR3*CT3*(1-1.6674*POWER(CS3/CT3,-0.768)))+IF(V3=0,0,V3*CV3*CX3*(1-1.6674*POWER(CW3/CX3,-0.768)))+IF(CZ3=0,0,CZ3*BY2*CA2*(1-1.6674*POWER(BZ3/CA3,-0.768)))+IF(DB3=0,0,DB3*CC2*CE2*(1-1.6674*POWER(CD2/CE2,-0.768)))) -> 0 | BY3: =IF(AI3="",VLOOKUP($M3,'HU-MOD-2-Parameters_CROP'!$A$4:$AE$151,5,),AI3) -> 0.2 | BZ3: =IF(AJ3="",VLOOKUP($M3,'HU-MOD-2-Parameters_CROP'!$A$4:$AE$151,6,),AJ3) -> 0.46 | CA3: =IF(AK3="",VLOOKUP($M3,'HU-MOD-2-Parameters_CROP'!$A$4:$AE$151,7,),AK3) -> 0.0286 | CB3: =IF(AD3="",$AB3*VLOOKUP($M3,'HU-MOD-2-Parameters_CROP'!$A$4:$AE$201,8,),AD3) -> 0 | CC3: =IF(AL3="",VLOOKUP($M3,'HU-MOD-2-Parameters_CROP'!$A$4:$AE$151,9,),AL3) -> 0 | CD3: =IF(AM3="",VLOOKUP($M3,'HU-MOD-2-Parameters_CROP'!$A$4:$AE$151,10,),AM3) -> 0.46 | CE3: =IF(AN3="",VLOOKUP($M3,'HU-MOD-2-Parameters_CROP'!$A$4:$AE$151,11,),AN3) -> 0.0286 | CF3: =IF(AF3="",$AB3*VLOOKUP($M3,'HU-MOD-2-Parameters_CROP'!$A$4:$AE$201,12,),AF3) -> 0 | CG3: =IF(AO3="",VLOOKUP($M3,'HU-MOD-2-Parameters_CROP'!$A$4:$AE$151,13,),AO3) -> 0 | CH3: =IF(AP3="",VLOOKUP($M3,'HU-MOD-2-Parameters_CROP'!$A$4:$AE$151,14,),AP3) -> 0 | CI3: =IF(AQ3="",VLOOKUP($M3,'HU-MOD-2-Parameters_CROP'!$A$4:$AE$151,15,),AQ3) -> 0 | CJ3: =IF(AG3="",$AB3*VLOOKUP($M3,'HU-MOD-2-Parameters_CROP'!$A$4:$AE$201,16,),AG3) -> 12 | CK3: =IF(AR3="",VLOOKUP($M3,'HU-MOD-2-Parameters_CROP'!$A$4:$AE$151,17,),AR3) -> 0 | CL3: =IF(AS3="",VLOOKUP($M3,'HU-MOD-2-Parameters_CROP'!$A$4:$AE$151,18,),AS3) -> 0.46 | CM3: =IF(AT3="",VLOOKUP($M3,'HU-MOD-2-Parameters_CROP'!$A$4:$AE$151,19,),AT3) -> 0.0286 | CN3: =IF(AH3="",$AB3*BY3*VLOOKUP($M3,'HU-MOD-2-Parameters_CROP'!$A$4:$AE$201,20,),AH3) -> 12 | CO3: =IF(AU3="",VLOOKUP($M3,'HU-MOD-2-Parameters_CROP'!$A$4:$AE$151,21,),AU3) -> 1 | CP3: =IF(AV3="",VLOOKUP($M3,'HU-MOD-2-Parameters_CROP'!$A$4:$AE$151,22,),AV3) -> 0.4 | CQ3: =IF(AW3="",VLOOKUP($M3,'HU-MOD-2-Parameters_CROP'!$A$4:$AE$151,23,),AW3) -> 0.0204 | CR3: =IF(AX3="",VLOOKUP($Q3,'HU-MOD-2-Parameters_FTLZ'!$A$4:$I$109,5,),AX3) -> 0 | CS3: =IF(AY3="",VLOOKUP($Q3,'HU-MOD-2-Parameters_FTLZ'!$A$4:$I$109,6,),AY3) -> 0 | CT3: =IF(AZ3="",VLOOKUP($Q3,'HU-MOD-2-Parameters_FTLZ'!$A$4:$I$109,7,),AZ3) -> 0 | CU3: =IF(CR3=0,0,IF(S3=1,1000*R3*CR3*CT3*(1.6674*POWER(CS3/CT3,-0.768))*DI3,1000*R3*CR3*CT3*(1.6674*POWER(CS3/CT3,-0.768))*DH3)) -> 0 | CV3: =IF(BA3="",VLOOKUP($U3,'HU-MOD-2-Parameters_FTLZ'!$A$4:$I$109,5,),BA3) -> 0 | CW3: =IF(BB3="",VLOOKUP($U3,'HU-MOD-2-Parameters_FTLZ'!$A$4:$I$109,6,),BB3) -> 0 | CX3: =IF(BC3="",VLOOKUP($U3,'HU-MOD-2-Parameters_FTLZ'!$A$4:$I$109,7,),BC3) -> 0 | CY3: =IF(CV3=0,0,IF(W3=1,1000*V3*CV3*CX3*(1.6674*POWER(CW3/CX3,-0.768))*DM3,1000*V3*CV3*CX3*(1.6674*POWER(CW3/CX3,-0.768))*DL3)) -> 0 | CZ3: =IF(X3="",IF(AC2="Y",AB2,0),X3) -> 0 | DA3: =IF(AC2="Y",IF(Y3=1,1000*CZ3*BY2*CA2*1.6674*POWER(BZ2/CA2,-0.768)*DI3,1000*CZ3*BY2*CA2*1.6674*POWER(BZ2/CA2,-0.768)*DH3),0) -> 0 | DB3: =IF(Z3="",IF(AE2="Y",CB2,0),Z3) -> 0 | DC3: =IF(AE2="Y",IF(AB3=1,1000*DB3*CC2*CE2*1.6674*POWER(CD2/CE2,-0.768)*DI3,1000*DB3*CC2*CE2*1.6674*POWER(CD2/CE2,-0.768)*DH3),0) -> 0 | DE3: =IF(N3="",VLOOKUP(M3,'HU-MOD-2-Parameters_CROP'!$A$4:$AE$151,24,),N3) -> 0.9 | DF3: =IF(BG3="",VLOOKUP(M3,'HU-MOD-2-Parameters_CROP'!$A$4:$AE$151,25,),BG3) -> 0.85 | DG3: =IF(BH3="",VLOOKUP(M3,'HU-MOD-2-Parameters_CROP'!$A$4:$AE$151,26,),BH3) -> 0 | DH3: 1 | DI3: =1-POWER(((G3/10*H3)/(G3/10*H3+F3)),0.5*90) -> 0.42331874 | DJ3: 0.6
BI4: =E4*(IF(0<BO4-BP4-BQ4-BR4,BO4-BP4-BQ4-BR4,0)-BS4) -> #DIV/0! | BJ4: =IF((BV4+BW4)*E4<BT4+BU4,(BV4+BW4)*E4,BT4+BU4) -> 0 | BK4: =BJ4-BI4 -> #DIV/0! | BL4: =BK4/E4 -> #DIV/0! | BM4: =IF($J5=$J4,BK5+BK4,IF($J3=$J4,"",BK4)) -> #DIV/0! | BN4: =IF($J5=$J4,BL5+BL4,IF($J3=$J4,"",BL4)) -> #DIV/0! | BO4: =1000*(AB4*BY4*CA4+CB4*CC4*CE4+CF4*CG4*CI4+CJ4*CK4*CM4+CN4*CO4*CQ4) -> 0 | BP4: =IF(0<BO4*DE4*DF4-BQ4-BR4,BO4*DE4*DF4-BQ4-BR4,0) -> #DIV/0! | BQ4: =IF(BO4*DJ4>CU4+CY4+DA4+DC4+O4,CU4+CY4+DA4+DC4+O4,BO4*DJ4) -> 0 | BR4: =I4*DI4 -> #DIV/0! | BS4: =DG4*(1-DI4) -> #DIV/0! | BT4: =1000*(CF4*CG4*CH4+CJ4*CK4*CL4+CN4*CO4*CP4) -> 0 | BU4: =1000*(R4*CR4*CS4+V4*CV4*CW4+CZ4*BY3*BZ3+DB4*CC3*CD3) -> 0 | BV4: =1000*(CF4*CG4*CI4+CJ4*CK4*CM4+CN4*CO4*CQ4) -> 0 | BW4: =1000*(IF(R4=0,0,R4*CR4*CT4*(1-1.6674*POWER(CS4/CT4,-0.768)))+IF(V4=0,0,V4*CV4*CX4*(1-1.6674*POWER(CW4/CX4,-0.768)))+IF(CZ4=0,0,CZ4*BY3*CA3*(1-1.6674*POWER(BZ4/CA4,-0.768)))+IF(DB4=0,0,DB4*CC3*CE3*(1-1.6674*POWER(CD3/CE3,-0.768)))) -> 0 | BY4: =IF(AI4="",VLOOKUP($M4,'HU-MOD-2-Parameters_CROP'!$A$4:$AE$151,5,),AI4) -> 0 | BZ4: =IF(AJ4="",VLOOKUP($M4,'HU-MOD-2-Parameters_CROP'!$A$4:$AE$151,6,),AJ4) -> 0 | CA4: =IF(AK4="",VLOOKUP($M4,'HU-MOD-2-Parameters_CROP'!$A$4:$AE$151,7,),AK4) -> 0 | CB4: =IF(AD4="",$AB4*VLOOKUP($M4,'HU-MOD-2-Parameters_CROP'!$A$4:$AE$201,8,),AD4) -> 0 | CC4: =IF(AL4="",VLOOKUP($M4,'HU-MOD-2-Parameters_CROP'!$A$4:$AE$151,9,),AL4) -> 0 | CD4: =IF(AM4="",VLOOKUP($M4,'HU-MOD-2-Parameters_CROP'!$A$4:$AE$151,10,),AM4) -> 0 | CE4: =IF(AN4="",VLOOKUP($M4,'HU-MOD-2-Parameters_CROP'!$A$4:$AE$151,11,),AN4) -> 0 | CF4: =IF(AF4="",$AB4*VLOOKUP($M4,'HU-MOD-2-Parameters_CROP'!$A$4:$AE$201,12,),AF4) -> 0 | CG4: =IF(AO4="",VLOOKUP($M4,'HU-MOD-2-Parameters_CROP'!$A$4:$AE$151,13,),AO4) -> 0 | CH4: =IF(AP4="",VLOOKUP($M4,'HU-MOD-2-Parameters_CROP'!$A$4:$AE$151,14,),AP4) -> 0 | CI4: =IF(AQ4="",VLOOKUP($M4,'HU-MOD-2-Parameters_CROP'!$A$4:$AE$151,15,),AQ4) -> 0 | CJ4: =IF(AG4="",$AB4*VLOOKUP($M4,'HU-MOD-2-Parameters_CROP'!$A$4:$AE$201,16,),AG4) -> 0 | CK4: =IF(AR4="",VLOOKUP($M4,'HU-MOD-2-Parameters_CROP'!$A$4:$AE$151,17,),AR4) -> 0 | CL4: =IF(AS4="",VLOOKUP($M4,'HU-MOD-2-Parameters_CROP'!$A$4:$AE$151,18,),AS4) -> 0 | CM4: =IF(AT4="",VLOOKUP($M4,'HU-MOD-2-Parameters_CROP'!$A$4:$AE$151,19,),AT4) -> 0 | CN4: =IF(AH4="",$AB4*BY4*VLOOKUP($M4,'HU-MOD-2-Parameters_CROP'!$A$4:$AE$201,20,),AH4) -> 0 | CO4: =IF(AU4="",VLOOKUP($M4,'HU-MOD-2-Parameters_CROP'!$A$4:$AE$151,21,),AU4) -> 0 | CP4: =IF(AV4="",VLOOKUP($M4,'HU-MOD-2-Parameters_CROP'!$A$4:$AE$151,22,),AV4) -> 0 | CQ4: =IF(AW4="",VLOOKUP($M4,'HU-MOD-2-Parameters_CROP'!$A$4:$AE$151,23,),AW4) -> 0 | CR4: =IF(AX4="",VLOOKUP($Q4,'HU-MOD-2-Parameters_FTLZ'!$A$4:$I$109,5,),AX4) -> 0 | CS4: =IF(AY4="",VLOOKUP($Q4,'HU-MOD-2-Parameters_FTLZ'!$A$4:$I$109,6,),AY4) -> 0 | CT4: =IF(AZ4="",VLOOKUP($Q4,'HU-MOD-2-Parameters_FTLZ'!$A$4:$I$109,7,),AZ4) -> 0 | CU4: =IF(CR4=0,0,IF(S4=1,1000*R4*CR4*CT4*(1.6674*POWER(CS4/CT4,-0.768))*DI4,1000*R4*CR4*CT4*(1.6674*POWER(CS4/CT4,-0.768))*DH4)) -> 0 | CV4: =IF(BA4="",VLOOKUP($U4,'HU-MOD-2-Parameters_FTLZ'!$A$4:$I$109,5,),BA4) -> 0 | CW4: =IF(BB4="",VLOOKUP($U4,'HU-MOD-2-Parameters_FTLZ'!$A$4:$I$109,6,),BB4) -> 0 | CX4: =IF(BC4="",VLOOKUP($U4,'HU-MOD-2-Parameters_FTLZ'!$A$4:$I$109,7,),BC4) -> 0 | CY4: =IF(CV4=0,0,IF(W4=1,1000*V4*CV4*CX4*(1.6674*POWER(CW4/CX4,-0.768))*DM4,1000*V4*CV4*CX4*(1.6674*POWER(CW4/CX4,-0.768))*DL4)) -> 0 | CZ4: =IF(X4="",IF(AC3="Y",AB3,0),X4) -> 0 | DA4: =IF(AC3="Y",IF(Y4=1,1000*CZ4*BY3*CA3*1.6674*POWER(BZ3/CA3,-0.768)*DI4,1000*CZ4*BY3*CA3*1.6674*POWER(BZ3/CA3,-0.768)*DH4),0) -> 0 | DB4: =IF(Z4="",IF(AE3="Y",CB3,0),Z4) -> 0 | DC4: =IF(AE3="Y",IF(AB4=1,1000*DB4*CC3*CE3*1.6674*POWER(CD3/CE3,-0.768)*DI4,1000*DB4*CC3*CE3*1.6674*POWER(CD3/CE3,-0.768)*DH4),0) -> 0 | DE4: =IF(N4="",VLOOKUP(M4,'HU-MOD-2-Parameters_CROP'!$A$4:$AE$151,24,),N4) -> 0 | DF4: =IF(BG4="",VLOOKUP(M4,'HU-MOD-2-Parameters_CROP'!$A$4:$AE$151,25,),BG4) -> 0 | DG4: =IF(BH4="",VLOOKUP(M4,'HU-MOD-2-Parameters_CROP'!$A$4:$AE$151,26,),BH4) -> 0 | DH4: 1 | DI4: =1-POWER(((G4/10*H4)/(G4/10*H4+F4)),0.5*90) -> #DIV/0! | DJ4: 0.6
A5: Test Farm | B5: Organic Mixed Farm | E5: 10 | F5: 0.4 | G5: 650 | H5: 0.5 | I5: 20 | J5: 2000 | K5: 1 | L5: Winter rye | M5: 1004 | N5: 0 | O5: 0 | P5: Cattle manure | Q5: 1041 | R5: 45 | S5: 1 | AB5: 5.5 | AC5: N | AE5: N | BI5: =E5*(IF(0<BO5-BP5-BQ5-BR5,BO5-BP5-BQ5-BR5,0)-BS5) -> 1286.7483 | BJ5: =IF((BV5+BW5)*E5<BT5+BU5,(BV5+BW5)*E5,BT5+BU5) -> 2621.4054 | BK5: =BJ5-BI5 -> 1334.6572 | BL5: =BK5/E5 -> 133.46572 | BM5: =IF($J6=$J5,BK6+BK5,IF($J4=$J5,"",BK5)) -> 1334.6572 | BN5: =IF($J6=$J5,BL6+BL5,IF($J4=$J5,"",BL5)) -> 133.46572 | BO5: =1000*(AB5*BY5*CA5+CB5*CC5*CE5+CF5*CG5*CI5+CJ5*CK5*CM5+CN5*CO5*CQ5) -> 160.74792 | BP5: =IF(0<BO5*DE5*DF5-BQ5-BR5,BO5*DE5*DF5-BQ5-BR5,0) -> 0 | BQ5: =IF(BO5*DJ5>CU5+CY5+DA5+DC5+O5*DI5,CU5+CY5+DA5+DC5+O5*DI5,BO5*DJ5) -> 23.606722 | BR5: =I5*DI5 -> 8.4663749 | BS5: =DG5*(1-DI5) -> 0 | BT5: =1000*(CF5*CG5*CH5+CJ5*CK5*CL5+CN5*CO5*CP5) -> 1957.319 | BU5: =1000*(R5*CR5*CS5+V5*CV5*CW5+CZ5*BY4*BZ4+DB5*CC4*CD4) -> 4500 | BV5: =1000*(CF5*CG5*CI5+CJ5*CK5*CM5+CN5*CO5*CQ5) -> 36.656374 | BW5: =1000*(IF(R5=0,0,R5*CR5*CT5*(1-1.6674*POWER(CS5/CT5,-0.768)))+IF(V5=0,0,V5*CV5*CX5*(1-1.6674*POWER(CW5/CX5,-0.768)))+IF(CZ5=0,0,CZ5*BY4*CA4*(1-1.6674*POWER(BZ5/CA5,-0.768)))+IF(DB5=0,0,DB5*CC4*CE4*(1-1.6674*POWER(CD4/CE4,-0.768)))) -> 225.48417 | BY5: =IF(AI5="",VLOOKUP($M5,'HU-MOD-2-Parameters_CROP'!$A$4:$AE$151,5,),AI5) -> 0.86 | BZ5: =IF(AJ5="",VLOOKUP($M5,'HU-MOD-2-Parameters_CROP'!$A$4:$AE$151,6,),AJ5) -> 0.445 | CA5: =IF(AK5="",VLOOKUP($M5,'HU-MOD-2-Parameters_CROP'!$A$4:$AE$151,7,),AK5) -> 0.0198 | CB5: =IF(AD5="",$AB5*VLOOKUP($M5,'HU-MOD-2-Parameters_CROP'!$A$4:$AE$201,8,),AD5) -> 7.15 | CC5: =IF(AL5="",VLOOKUP($M5,'HU-MOD-2-Parameters_CROP'!$A$4:$AE$151,9,),AL5) -> 0.86 | CD5: =IF(AM5="",VLOOKUP($M5,'HU-MOD-2-Parameters_CROP'!$A$4:$AE$151,10,),AM5) -> 0.46 | CE5: =IF(AN5="",VLOOKUP($M5,'HU-MOD-2-Parameters_CROP'!$A$4:$AE$151,11,),AN5) -> 0.00495 | CF5: =IF(AF5="",$AB5*VLOOKUP($M5,'HU-MOD-2-Parameters_CROP'!$A$4:$AE$201,12,),AF5) -> 0 | CG5: =IF(AO5="",VLOOKUP($M5,'HU-MOD-2-Parameters_CROP'!$A$4:$AE$151,13,),AO5) -> 0 | CH5: =IF(AP5="",VLOOKUP($M5,'HU-MOD-2-Parameters_CROP'!$A$4:$AE$151,14,),AP5) -> 0 | CI5: =IF(AQ5="",VLOOKUP($M5,'HU-MOD-2-Parameters_CROP'!$A$4:$AE$151,15,),AQ5) -> 0 | CJ5: =IF(AG5="",$AB5*VLOOKUP($M5,'HU-MOD-2-Parameters_CROP'!$A$4:$AE$201,16,),AG5) -> 1.4404762 | CK5: =IF(AR5="",VLOOKUP($M5,'HU-MOD-2-Parameters_CROP'!$A$4:$AE$151,17,),AR5) -> 0.86 | CL5: =IF(AS5="",VLOOKUP($M5,'HU-MOD-2-Parameters_CROP'!$A$4:$AE$151,18,),AS5) -> 0.46 | CM5: =IF(AT5="",VLOOKUP($M5,'HU-MOD-2-Parameters_CROP'!$A$4:$AE$151,19,),AT5) -> 0.00495 | CN5: =IF(AH5="",$AB5*BY5*VLOOKUP($M5,'HU-MOD-2-Parameters_CROP'!$A$4:$AE$201,20,),AH5) -> 3.4686667 | CO5: =IF(AU5="",VLOOKUP($M5,'HU-MOD-2-Parameters_CROP'!$A$4:$AE$151,21,),AU5) -> 1 | CP5: =IF(AV5="",VLOOKUP($M5,'HU-MOD-2-Parameters_CROP'!$A$4:$AE$151,22,),AV5) -> 0.4 | CQ5: =IF(AW5="",VLOOKUP($M5,'HU-MOD-2-Parameters_CROP'!$A$4:$AE$151,23,),AW5) -> 0.0088 | CR5: =IF(AX5="",VLOOKUP($Q5,'HU-MOD-2-Parameters_FTLZ'!$A$4:$I$109,5,),AX5) -> 0.25 | CS5: =IF(AY5="",VLOOKUP($Q5,'HU-MOD-2-Parameters_FTLZ'!$A$4:$I$109,6,),AY5) -> 0.4 | CT5: =IF(AZ5="",VLOOKUP($Q5,'HU-MOD-2-Parameters_FTLZ'!$A$4:$I$109,7,),AZ5) -> 0.025 | CU5: =IF(CR5=0,0,IF(S5=1,1000*R5*CR5*CT5*(1.6674*POWER(CS5/CT5,-0.768))*DI5,1000*R5*CR5*CT5*(1.6674*POWER(CS5/CT5,-0.768))*DH5)) -> 23.606722 | CV5: =IF(BA5="",VLOOKUP($U5,'HU-MOD-2-Parameters_FTLZ'!$A$4:$I$109,5,),BA5) -> 0 | CW5: =IF(BB5="",VLOOKUP($U5,'HU-MOD-2-Parameters_FTLZ'!$A$4:$I$109,6,),BB5) -> 0 | CX5: =IF(BC5="",VLOOKUP($U5,'HU-MOD-2-Parameters_FTLZ'!$A$4:$I$109,7,),BC5) -> 0 | CY5: =IF(CV5=0,0,IF(W5=1,1000*V5*CV5*CX5*(1.6674*POWER(CW5/CX5,-0.768))*DI5,1000*V5*CV5*CX5*(1.6674*POWER(CW5/CX5,-0.768))*DH5)) -> 0 | CZ5: =IF(X5="",IF(AC4="Y",AB4,0),X5) -> 0 | DA5: =IF(AC4="Y",IF(Y5=1,1000*CZ5*BY4*CA4*1.6674*POWER(BZ4/CA4,-0.768)*DI5,1000*CZ5*BY4*CA4*1.6674*POWER(BZ4/CA4,-0.768)*DH5),0) -> 0 | DB5: =IF(Z5="",IF(AE4="Y",CB4,0),Z5) -> 0 | DC5: =IF(AE4="Y",IF(AB5=1,1000*DB5*CC4*CE4*1.6674*POWER(CD4/CE4,-0.768)*DI5,1000*DB5*CC4*CE4*1.6674*POWER(CD4/CE4,-0.768)*DH5),0) -> 0 | DE5: =IF(N5="",VLOOKUP(M5,'HU-MOD-2-Parameters_CROP'!$A$4:$AE$151,24,),N5) -> 0 | DF5: =IF(BG5="",VLOOKUP(M5,'HU-MOD-2-Parameters_CROP'!$A$4:$AE$151,25,),BG5) -> 0 | DG5: =IF(BH5="",VLOOKUP(M5,'HU-MOD-2-Parameters_CROP'!$A$4:$AE$151,26,),BH5) -> 0 | DH5: 1 | DI5: =1-POWER(((G5/10*H5)/(G5/10*H5+F5)),0.5*90) -> 0.42331874 | DJ5: 0.6
A6: Test Farm | B6: Organic Mixed Farm | E6: 10 | F6: 0.4 | G6: 650 | H6: 0.5 | I6: 20 | J6: 2001 | K6: 1 | L6: Clover grass | M6: 1050 | N6: 0.9 | O6: 0 | AB6: 30 | AC6: N | BI6: =E6*(IF(0<BO6-BP6-BQ6-BR6,BO6-BP6-BQ6-BR6,0)-BS6) -> 690.9 | BJ6: =IF((BV6+BW6)*E6<BT6+BU6,(BV6+BW6)*E6,BT6+BU6) -> 1224 | BK6: =BJ6-BI6 -> 533.1 | BL6: =BK6/E6 -> 53.31 | BM6: =IF($J7=$J6,BK7+BK6,IF($J5=$J6,"",BK6)) -> 646.38 | BN6: =IF($J7=$J6,BL7+BL6,IF($J5=$J6,"",BL6)) -> 64.638 | BO6: =1000*(AB6*BY6*CA6+CB6*CC6*CE6+CF6*CG6*CI6+CJ6*CK6*CM6+CN6*CO6*CQ6) -> 294 | BP6: =IF(0<BO6*DE6*DF6-BQ6-BR6,BO6*DE6*DF6-BQ6-BR6,0) -> 216.44363 | BQ6: =IF(BO6*DJ6>CU6+CY6+DA6+DC6+O6,CU6+CY6+DA6+DC6+O6,BO6*DJ6) -> 0 | BR6: =I6*DI6 -> 8.4663749 | BS6: =DG6*(1-DI6) -> 0 | BT6: =1000*(CF6*CG6*CH6+CJ6*CK6*CL6+CN6*CO6*CP6) -> 2400 | BU6: =1000*(R6*CR6*CS6+V6*CV6*CW6+CZ6*BY5*BZ5+DB6*CC5*CD5) -> 0 | BV6: =1000*(CF6*CG6*CI6+CJ6*CK6*CM6+CN6*CO6*CQ6) -> 122.4 | BW6: =1000*(IF(R6=0,0,R6*CR6*CT6*(1-1.6674*POWER(CS6/CT6,-0.768)))+IF(V6=0,0,V6*CV6*CX6*(1-1.6674*POWER(CW6/CX6,-0.768)))+IF(CZ6=0,0,CZ6*BY5*CA5*(1-1.6674*POWER(BZ6/CA6,-0.768)))+IF(DB6=0,0,DB6*CC5*CE5*(1-1.6674*POWER(CD5/CE5,-0.768)))) -> 0 | BY6: =IF(AI6="",VLOOKUP($M6,'HU-MOD-2-Parameters_CROP'!$A$4:$AE$151,5,),AI6) -> 0.2 | BZ6: =IF(AJ6="",VLOOKUP($M6,'HU-MOD-2-Parameters_CROP'!$A$4:$AE$151,6,),AJ6) -> 0.46 | CA6: =IF(AK6="",VLOOKUP($M6,'HU-MOD-2-Parameters_CROP'!$A$4:$AE$151,7,),AK6) -> 0.0286 | CB6: =IF(AD6="",$AB6*VLOOKUP($M6,'HU-MOD-2-Parameters_CROP'!$A$4:$AE$201,8,),AD6) -> 0 | CC6: =IF(AL6="",VLOOKUP($M6,'HU-MOD-2-Parameters_CROP'!$A$4:$AE$151,9,),AL6) -> 0 | CD6: =IF(AM6="",VLOOKUP($M6,'HU-MOD-2-Parameters_CROP'!$A$4:$AE$151,10,),AM6) -> 0.46 | CE6: =IF(AN6="",VLOOKUP($M6,'HU-MOD-2-Parameters_CROP'!$A$4:$AE$151,11,),AN6) -> 0.0286 | CF6: =IF(AF6="",$AB6*VLOOKUP($M6,'HU-MOD-2-Parameters_CROP'!$A$4:$AE$201,12,),AF6) -> 0 | CG6: =IF(AO6="",VLOOKUP($M6,'HU-MOD-2-Parameters_CROP'!$A$4:$AE$151,13,),AO6) -> 0 | CH6: =IF(AP6="",VLOOKUP($M6,'HU-MOD-2-Parameters_CROP'!$A$4:$AE$151,14,),AP6) -> 0 | CI6: =IF(AQ6="",VLOOKUP($M6,'HU-MOD-2-Parameters_CROP'!$A$4:$AE$151,15,),AQ6) -> 0 | CJ6: =IF(AG6="",$AB6*VLOOKUP($M6,'HU-MOD-2-Parameters_CROP'!$A$4:$AE$201,16,),AG6) -> 6 | CK6: =IF(AR6="",VLOOKUP($M6,'HU-MOD-2-Parameters_CROP'!$A$4:$AE$151,17,),AR6) -> 0 | CL6: =IF(AS6="",VLOOKUP($M6,'HU-MOD-2-Parameters_CROP'!$A$4:$AE$151,18,),AS6) -> 0.46 | CM6: =IF(AT6="",VLOOKUP($M6,'HU-MOD-2-Parameters_CROP'!$A$4:$AE$151,19,),AT6) -> 0.0286 | CN6: =IF(AH6="",$AB6*BY6*VLOOKUP($M6,'HU-MOD-2-Parameters_CROP'!$A$4:$AE$201,20,),AH6) -> 6 | CO6: =IF(AU6="",VLOOKUP($M6,'HU-MOD-2-Parameters_CROP'!$A$4:$AE$151,21,),AU6) -> 1 | CP6: =IF(AV6="",VLOOKUP($M6,'HU-MOD-2-Parameters_CROP'!$A$4:$AE$151,22,),AV6) -> 0.4 | CQ6: =IF(AW6="",VLOOKUP($M6,'HU-MOD-2-Parameters_CROP'!$A$4:$AE$151,23,),AW6) -> 0.0204 | CR6: =IF(AX6="",VLOOKUP($Q6,'HU-MOD-2-Parameters_FTLZ'!$A$4:$I$109,5,),AX6) -> 0 | CS6: =IF(AY6="",VLOOKUP($Q6,'HU-MOD-2-Parameters_FTLZ'!$A$4:$I$109,6,),AY6) -> 0 | CT6: =IF(AZ6="",VLOOKUP($Q6,'HU-MOD-2-Parameters_FTLZ'!$A$4:$I$109,7,),AZ6) -> 0 | CU6: =IF(CR6=0,0,IF(S6=1,1000*R6*CR6*CT6*(1.6674*POWER(CS6/CT6,-0.768))*DI6,1000*R6*CR6*CT6*(1.6674*POWER(CS6/CT6,-0.768))*DH6)) -> 0 | CV6: =IF(BA6="",VLOOKUP($U6,'HU-MOD-2-Parameters_FTLZ'!$A$4:$I$109,5,),BA6) -> 0 | CW6: =IF(BB6="",VLOOKUP($U6,'HU-MOD-2-Parameters_FTLZ'!$A$4:$I$109,6,),BB6) -> 0 | CX6: =IF(BC6="",VLOOKUP($U6,'HU-MOD-2-Parameters_FTLZ'!$A$4:$I$109,7,),BC6) -> 0 | CY6: =IF(CV6=0,0,IF(W6=1,1000*V6*CV6*CX6*(1.6674*POWER(CW6/CX6,-0.768))*DM6,1000*V6*CV6*CX6*(1.6674*POWER(CW6/CX6,-0.768))*DL6)) -> 0 | CZ6: =IF(X6="",IF(AC5="Y",AB5,0),X6) -> 0 | DA6: =IF(AC5="Y",IF(Y6=1,1000*CZ6*BY5*CA5*1.6674*POWER(BZ5/CA5,-0.768)*DI6,1000*CZ6*BY5*CA5*1.6674*POWER(BZ5/CA5,-0.768)*DH6),0) -> 0 | DB6: =IF(Z6="",IF(AE5="Y",CB5,0),Z6) -> 0 | DC6: =IF(AE5="Y",IF(AB6=1,1000*DB6*CC5*CE5*1.6674*POWER(CD5/CE5,-0.768)*DI6,1000*DB6*CC5*CE5*1.6674*POWER(CD5/CE5,-0.768)*DH6),0) -> 0 | DE6: =IF(N6="",VLOOKUP(M6,'HU-MOD-2-Parameters_CROP'!$A$4:$AE$151,24,),N6) -> 0.9 | DF6: =IF(BG6="",VLOOKUP(M6,'HU-MOD-2-Parameters_CROP'!$A$4:$AE$151,25,),BG6) -> 0.85 | DG6: =IF(BH6="",VLOOKUP(M6,'HU-MOD-2-Parameters_CROP'!$A$4:$AE$151,26,),BH6) -> 0 | DH6: 1 | DI6: =1-POWER(((G6/10*H6)/(G6/10*H6+F6)),0.5*90) -> 0.42331874 | DJ6: 0.6
A7: Test Farm | B7: Organic Mixed Farm | E7: 10 | F7: 0.4 | G7: 650 | H7: 0.5 | I7: 20 | J7: 2001 | K7: 2 | L7: Clover grass | M7: 1050 | N7: 0.8 | O7: 0 | AB7: 12 | AC7: N | BI7: =E7*(IF(0<BO7-BP7-BQ7-BR7,BO7-BP7-BQ7-BR7,0)-BS7) -> 376.32 | BJ7: =IF((BV7+BW7)*E7<BT7+BU7,(BV7+BW7)*E7,BT7+BU7) -> 489.6 | BK7: =BJ7-BI7 -> 113.28 | BL7: =BK7/E7 -> 11.328 | BM7: =IF($J8=$J7,BK8+BK7,IF($J6=$J7,"",BK7)) -> 124.38 | BN7: =IF($J8=$J7,BL8+BL7,IF($J6=$J7,"",BL7)) -> 12.438 | BO7: =1000*(AB7*BY7*CA7+CB7*CC7*CE7+CF7*CG7*CI7+CJ7*CK7*CM7+CN7*CO7*CQ7) -> 117.6 | BP7: =IF(0<BO7*DE7*DF7-BQ7-BR7,BO7*DE7*DF7-BQ7-BR7,0) -> 71.501625 | BQ7: =IF(BO7*DJ7>CU7+CY7+DA7+DC7+O7,CU7+CY7+DA7+DC7+O7,BO7*DJ7) -> 0 | BR7: =I7*DI7 -> 8.4663749 | BS7: =DG7*(1-DI7) -> 0 | BT7: =1000*(CF7*CG7*CH7+CJ7*CK7*CL7+CN7*CO7*CP7) -> 960 | BU7: =1000*(R7*CR7*CS7+V7*CV7*CW7+CZ7*BY6*BZ6+DB7*CC6*CD6) -> 0 | BV7: =1000*(CF7*CG7*CI7+CJ7*CK7*CM7+CN7*CO7*CQ7) -> 48.96 | BW7: =1000*(IF(R7=0,0,R7*CR7*CT7*(1-1.6674*POWER(CS7/CT7,-0.768)))+IF(V7=0,0,V7*CV7*CX7*(1-1.6674*POWER(CW7/CX7,-0.768)))+IF(CZ7=0,0,CZ7*BY6*CA6*(1-1.6674*POWER(BZ7/CA7,-0.768)))+IF(DB7=0,0,DB7*CC6*CE6*(1-1.6674*POWER(CD6/CE6,-0.768)))) -> 0 | BY7: =IF(AI7="",VLOOKUP($M7,'HU-MOD-2-Parameters_CROP'!$A$4:$AE$151,5,),AI7) -> 0.2 | BZ7: =IF(AJ7="",VLOOKUP($M7,'HU-MOD-2-Parameters_CROP'!$A$4:$AE$151,6,),AJ7) -> 0.46 | CA7: =IF(AK7="",VLOOKUP($M7,'HU-MOD-2-Parameters_CROP'!$A$4:$AE$151,7,),AK7) -> 0.0286 | CB7: =IF(AD7="",$AB7*VLOOKUP($M7,'HU-MOD-2-Parameters_CROP'!$A$4:$AE$201,8,),AD7) -> 0 | CC7: =IF(AL7="",VLOOKUP($M7,'HU-MOD-2-Parameters_CROP'!$A$4:$AE$151,9,),AL7) -> 0 | CD7: =IF(AM7="",VLOOKUP($M7,'HU-MOD-2-Parameters_CROP'!$A$4:$AE$151,10,),AM7) -> 0.46 | CE7: =IF(AN7="",VLOOKUP($M7,'HU-MOD-2-Parameters_CROP'!$A$4:$AE$151,11,),AN7) -> 0.0286 | CF7: =IF(AF7="",$AB7*VLOOKUP($M7,'HU-MOD-2-Parameters_CROP'!$A$4:$AE$201,12,),AF7) -> 0 | CG7: =IF(AO7="",VLOOKUP($M7,'HU-MOD-2-Parameters_CROP'!$A$4:$AE$151,13,),AO7) -> 0 | CH7: =IF(AP7="",VLOOKUP($M7,'HU-MOD-2-Parameters_CROP'!$A$4:$AE$151,14,),AP7) -> 0 | CI7: =IF(AQ7="",VLOOKUP($M7,'HU-MOD-2-Parameters_CROP'!$A$4:$AE$151,15,),AQ7) -> 0 | CJ7: =IF(AG7="",$AB7*VLOOKUP($M7,'HU-MOD-2-Parameters_CROP'!$A$4:$AE$201,16,),AG7) -> 2.4 | CK7: =IF(AR7="",VLOOKUP($M7,'HU-MOD-2-Parameters_CROP'!$A$4:$AE$151,17,),AR7) -> 0 | CL7: =IF(AS7="",VLOOKUP($M7,'HU-MOD-2-Parameters_CROP'!$A$4:$AE$151,18,),AS7) -> 0.46 | CM7: =IF(AT7="",VLOOKUP($M7,'HU-MOD-2-Parameters_CROP'!$A$4:$AE$151,19,),AT7) -> 0.0286 | CN7: =IF(AH7="",$AB7*BY7*VLOOKUP($M7,'HU-MOD-2-Parameters_CROP'!$A$4:$AE$201,20,),AH7) -> 2.4 | CO7: =IF(AU7="",VLOOKUP($M7,'HU-MOD-2-Parameters_CROP'!$A$4:$AE$151,21,),AU7) -> 1 | CP7: =IF(AV7="",VLOOKUP($M7,'HU-MOD-2-Parameters_CROP'!$A$4:$AE$151,22,),AV7) -> 0.4 | CQ7: =IF(AW7="",VLOOKUP($M7,'HU-MOD-2-Parameters_CROP'!$A$4:$AE$151,23,),AW7) -> 0.0204 | CR7: =IF(AX7="",VLOOKUP($Q7,'HU-MOD-2-Parameters_FTLZ'!$A$4:$I$109,5,),AX7) -> 0 | CS7: =IF(AY7="",VLOOKUP($Q7,'HU-MOD-2-Parameters_FTLZ'!$A$4:$I$109,6,),AY7) -> 0 | CT7: =IF(AZ7="",VLOOKUP($Q7,'HU-MOD-2-Parameters_FTLZ'!$A$4:$I$109,7,),AZ7) -> 0 | CU7: =IF(CR7=0,0,IF(S7=1,1000*R7*CR7*CT7*(1.6674*POWER(CS7/CT7,-0.768))*DI7,1000*R7*CR7*CT7*(1.6674*POWER(CS7/CT7,-0.768))*DH7)) -> 0 | CV7: =IF(BA7="",VLOOKUP($U7,'HU-MOD-2-Parameters_FTLZ'!$A$4:$I$109,5,),BA7) -> 0 | CW7: =IF(BB7="",VLOOKUP($U7,'HU-MOD-2-Parameters_FTLZ'!$A$4:$I$109,6,),BB7) -> 0 | CX7: =IF(BC7="",VLOOKUP($U7,'HU-MOD-2-Parameters_FTLZ'!$A$4:$I$109,7,),BC7) -> 0 | CY7: =IF(CV7=0,0,IF(W7=1,1000*V7*CV7*CX7*(1.6674*POWER(CW7/CX7,-0.768))*DM7,1000*V7*CV7*CX7*(1.6674*POWER(CW7/CX7,-0.768))*DL7)) -> 0 | CZ7: =IF(X7="",IF(AC6="Y",AB6,0),X7) -> 0 | DA7: =IF(AC6="Y",IF(Y7=1,1000*CZ7*BY6*CA6*1.6674*POWER(BZ6/CA6,-0.768)*DI7,1000*CZ7*BY6*CA6*1.6674*POWER(BZ6/CA6,-0.768)*DH7),0) -> 0 | DB7: =IF(Z7="",IF(AE6="Y",CB6,0),Z7) -> 0 | DC7: =IF(AE6="Y",IF(AB7=1,1000*DB7*CC6*CE6*1.6674*POWER(CD6/CE6,-0.768)*DI7,1000*DB7*CC6*CE6*1.6674*POWER(CD6/CE6,-0.768)*DH7),0) -> 0 | DE7: =IF(N7="",VLOOKUP(M7,'HU-MOD-2-Parameters_CROP'!$A$4:$AE$151,24,),N7) -> 0.8 | DF7: =IF(BG7="",VLOOKUP(M7,'HU-MOD-2-Parameters_CROP'!$A$4:$AE$151,25,),BG7) -> 0.85 | DG7: =IF(BH7="",VLOOKUP(M7,'HU-MOD-2-Parameters_CROP'!$A$4:$AE$151,26,),BH7) -> 0 | DH7: 1 | DI7: =1-POWER(((G7/10*H7)/(G7/10*H7+F7)),0.5*90) -> 0.42331874 | DJ7: 0.6
A8: Test Farm | B8: Organic Mixed Farm | E8: 10 | F8: 0.4 | G8: 650 | H8: 0.5 | I8: 20 | J8: 2001 | K8: 3 | L8: Clover grass | M8: 1050 | N8: 0.7 | O8: 0 | AB8: 10 | AC8: N | BI8: =E8*(IF(0<BO8-BP8-BQ8-BR8,BO8-BP8-BQ8-BR8,0)-BS8) -> 396.9 | BJ8: =IF((BV8+BW8)*E8<BT8+BU8,(BV8+BW8)*E8,BT8+BU8) -> 408 | BK8: =BJ8-BI8 -> 11.1 | BL8: =BK8/E8 -> 1.11 | BM8: =IF($J9=$J8,BK9+BK8,IF($J7=$J8,"",BK8)) -> -46.66 | BN8: =IF($J9=$J8,BL9+BL8,IF($J7=$J8,"",BL8)) -> -4.666 | BO8: =1000*(AB8*BY8*CA8+CB8*CC8*CE8+CF8*CG8*CI8+CJ8*CK8*CM8+CN8*CO8*CQ8) -> 98 | BP8: =IF(0<BO8*DE8*DF8-BQ8-BR8,BO8*DE8*DF8-BQ8-BR8,0) -> 49.843625 | BQ8: =IF(BO8*DJ8>CU8+CY8+DA8+DC8+O8,CU8+CY8+DA8+DC8+O8,BO8*DJ8) -> 0 | BR8: =I8*DI8 -> 8.4663749 | BS8: =DG8*(1-DI8) -> 0 | BT8: =1000*(CF8*CG8*CH8+CJ8*CK8*CL8+CN8*CO8*CP8) -> 800 | BU8: =1000*(R8*CR8*CS8+V8*CV8*CW8+CZ8*BY7*BZ7+DB8*CC7*CD7) -> 0 | BV8: =1000*(CF8*CG8*CI8+CJ8*CK8*CM8+CN8*CO8*CQ8) -> 40.8 | BW8: =1000*(IF(R8=0,0,R8*CR8*CT8*(1-1.6674*POWER(CS8/CT8,-0.768)))+IF(V8=0,0,V8*CV8*CX8*(1-1.6674*POWER(CW8/CX8,-0.768)))+IF(CZ8=0,0,CZ8*BY7*CA7*(1-1.6674*POWER(BZ8/CA8,-0.768)))+IF(DB8=0,0,DB8*CC7*CE7*(1-1.6674*POWER(CD7/CE7,-0.768)))) -> 0 | BY8: =IF(AI8="",VLOOKUP($M8,'HU-MOD-2-Parameters_CROP'!$A$4:$AE$151,5,),AI8) -> 0.2 | BZ8: =IF(AJ8="",VLOOKUP($M8,'HU-MOD-2-Parameters_CROP'!$A$4:$AE$151,6,),AJ8) -> 0.46 | CA8: =IF(AK8="",VLOOKUP($M8,'HU-MOD-2-Parameters_CROP'!$A$4:$AE$151,7,),AK8) -> 0.0286 | CB8: =IF(AD8="",$AB8*VLOOKUP($M8,'HU-MOD-2-Parameters_CROP'!$A$4:$AE$201,8,),AD8) -> 0 | CC8: =IF(AL8="",VLOOKUP($M8,'HU-MOD-2-Parameters_CROP'!$A$4:$AE$151,9,),AL8) -> 0 | CD8: =IF(AM8="",VLOOKUP($M8,'HU-MOD-2-Parameters_CROP'!$A$4:$AE$151,10,),AM8) -> 0.46 | CE8: =IF(AN8="",VLOOKUP($M8,'HU-MOD-2-Parameters_CROP'!$A$4:$AE$151,11,),AN8) -> 0.0286 | CF8: =IF(AF8="",$AB8*VLOOKUP($M8,'HU-MOD-2-Parameters_CROP'!$A$4:$AE$201,12,),AF8) -> 0 | CG8: =IF(AO8="",VLOOKUP($M8,'HU-MOD-2-Parameters_CROP'!$A$4:$AE$151,13,),AO8) -> 0 | CH8: =IF(AP8="",VLOOKUP($M8,'HU-MOD-2-Parameters_CROP'!$A$4:$AE$151,14,),AP8) -> 0 | CI8: =IF(AQ8="",VLOOKUP($M8,'HU-MOD-2-Parameters_CROP'!$A$4:$AE$151,15,),AQ8) -> 0 | CJ8: =IF(AG8="",$AB8*VLOOKUP($M8,'HU-MOD-2-Parameters_CROP'!$A$4:$AE$201,16,),AG8) -> 2 | CK8: =IF(AR8="",VLOOKUP($M8,'HU-MOD-2-Parameters_CROP'!$A$4:$AE$151,17,),AR8) -> 0 | CL8: =IF(AS8="",VLOOKUP($M8,'HU-MOD-2-Parameters_CROP'!$A$4:$AE$151,18,),AS8) -> 0.46 | CM8: =IF(AT8="",VLOOKUP($M8,'HU-MOD-2-Parameters_CROP'!$A$4:$AE$151,19,),AT8) -> 0.0286 | CN8: =IF(AH8="",$AB8*BY8*VLOOKUP($M8,'HU-MOD-2-Parameters_CROP'!$A$4:$AE$201,20,),AH8) -> 2 | CO8: =IF(AU8="",VLOOKUP($M8,'HU-MOD-2-Parameters_CROP'!$A$4:$AE$151,21,),AU8) -> 1 | CP8: =IF(AV8="",VLOOKUP($M8,'HU-MOD-2-Parameters_CROP'!$A$4:$AE$151,22,),AV8) -> 0.4 | CQ8: =IF(AW8="",VLOOKUP($M8,'HU-MOD-2-Parameters_CROP'!$A$4:$AE$151,23,),AW8) -> 0.0204 | CR8: =IF(AX8="",VLOOKUP($Q8,'HU-MOD-2-Parameters_FTLZ'!$A$4:$I$109,5,),AX8) -> 0 | CS8: =IF(AY8="",VLOOKUP($Q8,'HU-MOD-2-Parameters_FTLZ'!$A$4:$I$109,6,),AY8) -> 0 | CT8: =IF(AZ8="",VLOOKUP($Q8,'HU-MOD-2-Parameters_FTLZ'!$A$4:$I$109,7,),AZ8) -> 0 | CU8: =IF(CR8=0,0,IF(S8=1,1000*R8*CR8*CT8*(1.6674*POWER(CS8/CT8,-0.768))*DI8,1000*R8*CR8*CT8*(1.6674*POWER(CS8/CT8,-0.768))*DH8)) -> 0 | CV8: =IF(BA8="",VLOOKUP($U8,'HU-MOD-2-Parameters_FTLZ'!$A$4:$I$109,5,),BA8) -> 0 | CW8: =IF(BB8="",VLOOKUP($U8,'HU-MOD-2-Parameters_FTLZ'!$A$4:$I$109,6,),BB8) -> 0 | CX8: =IF(BC8="",VLOOKUP($U8,'HU-MOD-2-Parameters_FTLZ'!$A$4:$I$109,7,),BC8) -> 0 | CY8: =IF(CV8=0,0,IF(W8=1,1000*V8*CV8*CX8*(1.6674*POWER(CW8/CX8,-0.768))*DM8,1000*V8*CV8*CX8*(1.6674*POWER(CW8/CX8,-0.768))*DL8)) -> 0 | CZ8: =IF(X8="",IF(AC7="Y",AB7,0),X8) -> 0 | DA8: =IF(AC7="Y",IF(Y8=1,1000*CZ8*BY7*CA7*1.6674*POWER(BZ7/CA7,-0.768)*DI8,1000*CZ8*BY7*CA7*1.6674*POWER(BZ7/CA7,-0.768)*DH8),0) -> 0 | DB8: =IF(Z8="",IF(AE7="Y",CB7,0),Z8) -> 0 | DC8: =IF(AE7="Y",IF(AB8=1,1000*DB8*CC7*CE7*1.6674*POWER(CD7/CE7,-0.768)*DI8,1000*DB8*CC7*CE7*1.6674*POWER(CD7/CE7,-0.768)*DH8),0) -> 0 | DE8: =IF(N8="",VLOOKUP(M8,'HU-MOD-2-Parameters_CROP'!$A$4:$AE$151,24,),N8) -> 0.7 | DF8: =IF(BG8="",VLOOKUP(M8,'HU-MOD-2-Parameters_CROP'!$A$4:$AE$151,25,),BG8) -> 0.85 | DG8: =IF(BH8="",VLOOKUP(M8,'HU-MOD-2-Parameters_CROP'!$A$4:$AE$151,26,),BH8) -> 0 | DH8: 1 | DI8: =1-POWER(((G8/10*H8)/(G8/10*H8+F8)),0.5*90) -> 0.42331874 | DJ8: 0.6
A9: Test Farm | B9: Organic Mixed Farm | E9: 10 | F9: 0.4 | G9: 650 | H9: 0.5 | I9: 20 | J9: 2001 | K9: 4 | L9: Clover grass | M9: 1050 | N9: 0.6 | O9: 0 | AB9: 8 | AC9: Y | BI9: =E9*(IF(0<BO9-BP9-BQ9-BR9,BO9-BP9-BQ9-BR9,0)-BS9) -> 384.16 | BJ9: =IF((BV9+BW9)*E9<BT9+BU9,(BV9+BW9)*E9,BT9+BU9) -> 326.4 | BK9: =BJ9-BI9 -> -57.76 | BL9: =BK9/E9 -> -5.776 | BM9: =IF($J10=$J9,BK10+BK9,IF($J8=$J9,"",BK9)) | BN9: =IF($J10=$J9,BL10+BL9,IF($J8=$J9,"",BL9)) | BO9: =1000*(AB9*BY9*CA9+CB9*CC9*CE9+CF9*CG9*CI9+CJ9*CK9*CM9+CN9*CO9*CQ9) -> 78.4 | BP9: =IF(0<BO9*DE9*DF9-BQ9-BR9,BO9*DE9*DF9-BQ9-BR9,0) -> 31.517625 | BQ9: =IF(BO9*DJ9>CU9+CY9+DA9+DC9+O9,CU9+CY9+DA9+DC9+O9,BO9*DJ9) -> 0 | BR9: =I9*DI9 -> 8.4663749 | BS9: =DG9*(1-DI9) -> 0 | BT9: =1000*(CF9*CG9*CH9+CJ9*CK9*CL9+CN9*CO9*CP9) -> 640 | BU9: =1000*(R9*CR9*CS9+V9*CV9*CW9+CZ9*BY8*BZ8+DB9*CC8*CD8) -> 0 | BV9: =1000*(CF9*CG9*CI9+CJ9*CK9*CM9+CN9*CO9*CQ9) -> 32.64 | BW9: =1000*(IF(R9=0,0,R9*CR9*CT9*(1-1.6674*POWER(CS9/CT9,-0.768)))+IF(V9=0,0,V9*CV9*CX9*(1-1.6674*POWER(CW9/CX9,-0.768)))+IF(CZ9=0,0,CZ9*BY8*CA8*(1-1.6674*POWER(BZ9/CA9,-0.768)))+IF(DB9=0,0,DB9*CC8*CE8*(1-1.6674*POWER(CD8/CE8,-0.768)))) -> 0 | BY9: =IF(AI9="",VLOOKUP($M9,'HU-MOD-2-Parameters_CROP'!$A$4:$AE$151,5,),AI9) -> 0.2 | BZ9: =IF(AJ9="",VLOOKUP($M9,'HU-MOD-2-Parameters_CROP'!$A$4:$AE$151,6,),AJ9) -> 0.46 | CA9: =IF(AK9="",VLOOKUP($M9,'HU-MOD-2-Parameters_CROP'!$A$4:$AE$151,7,),AK9) -> 0.0286 | CB9: =IF(AD9="",$AB9*VLOOKUP($M9,'HU-MOD-2-Parameters_CROP'!$A$4:$AE$201,8,),AD9) -> 0 | CC9: =IF(AL9="",VLOOKUP($M9,'HU-MOD-2-Parameters_CROP'!$A$4:$AE$151,9,),AL9) -> 0 | CD9: =IF(AM9="",VLOOKUP($M9,'HU-MOD-2-Parameters_CROP'!$A$4:$AE$151,10,),AM9) -> 0.46 | CE9: =IF(AN9="",VLOOKUP($M9,'HU-MOD-2-Parameters_CROP'!$A$4:$AE$151,11,),AN9) -> 0.0286 | CF9: =IF(AF9="",$AB9*VLOOKUP($M9,'HU-MOD-2-Parameters_CROP'!$A$4:$AE$201,12,),AF9) -> 0 | CG9: =IF(AO9="",VLOOKUP($M9,'HU-MOD-2-Parameters_CROP'!$A$4:$AE$151,13,),AO9) -> 0 | CH9: =IF(AP9="",VLOOKUP($M9,'HU-MOD-2-Parameters_CROP'!$A$4:$AE$151,14,),AP9) -> 0 | CI9: =IF(AQ9="",VLOOKUP($M9,'HU-MOD-2-Parameters_CROP'!$A$4:$AE$151,15,),AQ9) -> 0 | CJ9: =IF(AG9="",$AB9*VLOOKUP($M9,'HU-MOD-2-Parameters_CROP'!$A$4:$AE$201,16,),AG9) -> 1.6 | CK9: =IF(AR9="",VLOOKUP($M9,'HU-MOD-2-Parameters_CROP'!$A$4:$AE$151,17,),AR9) -> 0 | CL9: =IF(AS9="",VLOOKUP($M9,'HU-MOD-2-Parameters_CROP'!$A$4:$AE$151,18,),AS9) -> 0.46 | CM9: =IF(AT9="",VLOOKUP($M9,'HU-MOD-2-Parameters_CROP'!$A$4:$AE$151,19,),AT9) -> 0.0286 | CN9: =IF(AH9="",$AB9*BY9*VLOOKUP($M9,'HU-MOD-2-Parameters_CROP'!$A$4:$AE$201,20,),AH9) -> 1.6 | CO9: =IF(AU9="",VLOOKUP($M9,'HU-MOD-2-Parameters_CROP'!$A$4:$AE$151,21,),AU9) -> 1 | CP9: =IF(AV9="",VLOOKUP($M9,'HU-MOD-2-Parameters_CROP'!$A$4:$AE$151,22,),AV9) -> 0.4 | CQ9: =IF(AW9="",VLOOKUP($M9,'HU-MOD-2-Parameters_CROP'!$A$4:$AE$151,23,),AW9) -> 0.0204 | CR9: =IF(AX9="",VLOOKUP($Q9,'HU-MOD-2-Parameters_FTLZ'!$A$4:$I$109,5,),AX9) -> 0 | CS9: =IF(AY9="",VLOOKUP($Q9,'HU-MOD-2-Parameters_FTLZ'!$A$4:$I$109,6,),AY9) -> 0 | CT9: =IF(AZ9="",VLOOKUP($Q9,'HU-MOD-2-Parameters_FTLZ'!$A$4:$I$109,7,),AZ9) -> 0 | CU9: =IF(CR9=0,0,IF(S9=1,1000*R9*CR9*CT9*(1.6674*POWER(CS9/CT9,-0.768))*DI9,1000*R9*CR9*CT9*(1.6674*POWER(CS9/CT9,-0.768))*DH9)) -> 0 | CV9: =IF(BA9="",VLOOKUP($U9,'HU-MOD-2-Parameters_FTLZ'!$A$4:$I$109,5,),BA9) -> 0 | CW9: =IF(BB9="",VLOOKUP($U9,'HU-MOD-2-Parameters_FTLZ'!$A$4:$I$109,6,),BB9) -> 0 | CX9: =IF(BC9="",VLOOKUP($U9,'HU-MOD-2-Parameters_FTLZ'!$A$4:$I$109,7,),BC9) -> 0 | CY9: =IF(CV9=0,0,IF(W9=1,1000*V9*CV9*CX9*(1.6674*POWER(CW9/CX9,-0.768))*DM9,1000*V9*CV9*CX9*(1.6674*POWER(CW9/CX9,-0.768))*DL9)) -> 0 | CZ9: =IF(X9="",IF(AC8="Y",AB8,0),X9) -> 0 | DA9: =IF(AC8="Y",IF(Y9=1,1000*CZ9*BY8*CA8*1.6674*POWER(BZ8/CA8,-0.768)*DI9,1000*CZ9*BY8*CA8*1.6674*POWER(BZ8/CA8,-0.768)*DH9),0) -> 0 | DB9: =IF(Z9="",IF(AE8="Y",CB8,0),Z9) -> 0 | DC9: =IF(AE8="Y",IF(AB9=1,1000*DB9*CC8*CE8*1.6674*POWER(CD8/CE8,-0.768)*DI9,1000*DB9*CC8*CE8*1.6674*POWER(CD8/CE8,-0.768)*DH9),0) -> 0 | DE9: =IF(N9="",VLOOKUP(M9,'HU-MOD-2-Parameters_CROP'!$A$4:$AE$151,24,),N9) -> 0.6 | DF9: =IF(BG9="",VLOOKUP(M9,'HU-MOD-2-Parameters_CROP'!$A$4:$AE$151,25,),BG9) -> 0.85 | DG9: =IF(BH9="",VLOOKUP(M9,'HU-MOD-2-Parameters_CROP'!$A$4:$AE$151,26,),BH9) -> 0 | DH9: 1 | DI9: =1-POWER(((G9/10*H9)/(G9/10*H9+F9)),0.5*90) -> 0.42331874 | DJ9: 0.6
A10: Test Farm | B10: Organic Mixed Farm | E10: 10 | F10: 0.4 | G10: 650 | H10: 0.5 | I10: 20 | J10: 2002 | K10: 1 | L10: Winter wheat | M10: 1001 | N10: 0 | O10: 0 | AB10: 6.5 | AC10: N | AE10: Y | BI10: =E10*(IF(0<BO10-BP10-BQ10-BR10,BO10-BP10-BQ10-BR10,0)-BS10) -> 1509.7938 | BJ10: =IF((BV10+BW10)*E10<BT10+BU10,(BV10+BW10)*E10,BT10+BU10) -> 689.00953 | BK10: =BJ10-BI10 -> -820.78426 | BL10: =BK10/E10 -> -82.078426 | BM10: =IF($J11=$J10,BK11+BK10,IF($J9=$J10,"",BK10)) -> -580.11341 | BN10: =IF($J11=$J10,BL11+BL10,IF($J9=$J10,"",BL10)) -> -58.011341 | BO10: =1000*(AB10*BY10*CA10+CB10*CC10*CE10+CF10*CG10*CI10+CJ10*CK10*CM10+CN10*CO10*CQ10) -> 168.4826 | BP10: =IF(0<BO10*DE10*DF10-BQ10-BR10,BO10*DE10*DF10-BQ10-BR10,0) -> 0 | BQ10: =IF(BO10*DJ10>CU10+CY10+DA10+DC10+O10*DI10,CU10+CY10+DA10+DC10+O10*DI10,BO10*DJ10) -> 9.0368466 | BR10: =I10*DI10 -> 8.4663749 | BS10: =DG10*(1-DI10) -> 0 | BT10: =1000*(CF10*CG10*CH10+CJ10*CK10*CL10+CN10*CO10*CP10) -> 1632.28 | BU10: =1000*(R10*CR10*CS10+V10*CV10*CW10+CZ10*BY9*BZ9+DB10*CC9*CD9) -> 736 | BV10: =1000*(CF10*CG10*CI10+CJ10*CK10*CM10+CN10*CO10*CQ10) -> 30.1301 | BW10: =1000*(IF(R10=0,0,R10*CR10*CT10*(1-1.6674*POWER(CS10/CT10,-0.768)))+IF(V10=0,0,V10*CV10*CX10*(1-1.6674*POWER(CW10/CX10,-0.768)))+IF(CZ10=0,0,CZ10*BY9*CA9*(1-1.6674*POWER(BZ10/CA10,-0.768)))+IF(DB10=0,0,DB10*CC9*CE9*(1-1.6674*POWER(CD9/CE9,-0.768)))) -> 38.770853 | BY10: =IF(AI10="",VLOOKUP($M10,'HU-MOD-2-Parameters_CROP'!$A$4:$AE$151,5,),AI10) -> 0.86 | BZ10: =IF(AJ10="",VLOOKUP($M10,'HU-MOD-2-Parameters_CROP'!$A$4:$AE$151,6,),AJ10) -> 0.445 | CA10: =IF(AK10="",VLOOKUP($M10,'HU-MOD-2-Parameters_CROP'!$A$4:$AE$151,7,),AK10) -> 0.0198 | CB10: =IF(AD10="",$AB10*VLOOKUP($M10,'HU-MOD-2-Parameters_CROP'!$A$4:$AE$201,8,),AD10) -> 6.5 | CC10: =IF(AL10="",VLOOKUP($M10,'HU-MOD-2-Parameters_CROP'!$A$4:$AE$151,9,),AL10) -> 0.86 | CD10: =IF(AM10="",VLOOKUP($M10,'HU-MOD-2-Parameters_CROP'!$A$4:$AE$151,10,),AM10) -> 0.46 | CE10: =IF(AN10="",VLOOKUP($M10,'HU-MOD-2-Parameters_CROP'!$A$4:$AE$151,11,),AN10) -> 0.00495 | CF10: =IF(AF10="",$AB10*VLOOKUP($M10,'HU-MOD-2-Parameters_CROP'!$A$4:$AE$201,12,),AF10) -> 0 | CG10: =IF(AO10="",VLOOKUP($M10,'HU-MOD-2-Parameters_CROP'!$A$4:$AE$151,13,),AO10) -> 0 | CH10: =IF(AP10="",VLOOKUP($M10,'HU-MOD-2-Parameters_CROP'!$A$4:$AE$151,14,),AP10) -> 0 | CI10: =IF(AQ10="",VLOOKUP($M10,'HU-MOD-2-Parameters_CROP'!$A$4:$AE$151,15,),AQ10) -> 0 | CJ10: =IF(AG10="",$AB10*VLOOKUP($M10,'HU-MOD-2-Parameters_CROP'!$A$4:$AE$201,16,),AG10) -> 1.3 | CK10: =IF(AR10="",VLOOKUP($M10,'HU-MOD-2-Parameters_CROP'!$A$4:$AE$151,17,),AR10) -> 0.86 | CL10: =IF(AS10="",VLOOKUP($M10,'HU-MOD-2-Parameters_CROP'!$A$4:$AE$151,18,),AS10) -> 0.46 | CM10: =IF(AT10="",VLOOKUP($M10,'HU-MOD-2-Parameters_CROP'!$A$4:$AE$151,19,),AT10) -> 0.00495 | CN10: =IF(AH10="",$AB10*BY10*VLOOKUP($M10,'HU-MOD-2-Parameters_CROP'!$A$4:$AE$201,20,),AH10) -> 2.795 | CO10: =IF(AU10="",VLOOKUP($M10,'HU-MOD-2-Parameters_CROP'!$A$4:$AE$151,21,),AU10) -> 1 | CP10: =IF(AV10="",VLOOKUP($M10,'HU-MOD-2-Parameters_CROP'!$A$4:$AE$151,22,),AV10) -> 0.4 | CQ10: =IF(AW10="",VLOOKUP($M10,'HU-MOD-2-Parameters_CROP'!$A$4:$AE$151,23,),AW10) -> 0.0088 | CR10: =IF(AX10="",VLOOKUP($Q10,'HU-MOD-2-Parameters_FTLZ'!$A$4:$I$109,5,),AX10) -> 0 | CS10: =IF(AY10="",VLOOKUP($Q10,'HU-MOD-2-Parameters_FTLZ'!$A$4:$I$109,6,),AY10) -> 0 | CT10: =IF(AZ10="",VLOOKUP($Q10,'HU-MOD-2-Parameters_FTLZ'!$A$4:$I$109,7,),AZ10) -> 0 | CU10: =IF(CR10=0,0,IF(S10=1,1000*R10*CR10*CT10*(1.6674*POWER(CS10/CT10,-0.768))*DI10,1000*R10*CR10*CT10*(1.6674*POWER(CS10/CT10,-0.768))*DH10)) -> 0 | CV10: =IF(BA10="",VLOOKUP($U10,'HU-MOD-2-Parameters_FTLZ'!$A$4:$I$109,5,),BA10) -> 0 | CW10: =IF(BB10="",VLOOKUP($U10,'HU-MOD-2-Parameters_FTLZ'!$A$4:$I$109,6,),BB10) -> 0 | CX10: =IF(BC10="",VLOOKUP($U10,'HU-MOD-2-Parameters_FTLZ'!$A$4:$I$109,7,),BC10) -> 0 | CY10: =IF(CV10=0,0,IF(W10=1,1000*V10*CV10*CX10*(1.6674*POWER(CW10/CX10,-0.768))*DI10,1000*V10*CV10*CX10*(1.6674*POWER(CW10/CX10,-0.768))*DH10)) -> 0 | CZ10: =IF(X10="",IF(AC9="Y",AB9,0),X10) -> 8 | DA10: =IF(AC9="Y",IF(Y10=1,1000*CZ10*BY9*CA9*1.6674*POWER(BZ9/CA9,-0.768)*DI10,1000*CZ10*BY9*CA9*1.6674*POWER(BZ9/CA9,-0.768)*DH10),0) -> 9.0368466 | DB10: =IF(Z10="",IF(AE9="Y",CB9,0),Z10) -> 0 | DC10: =IF(AE9="Y",IF(AB10=1,1000*DB10*CC9*CE9*1.6674*POWER(CD9/CE9,-0.768)*DI10,1000*DB10*CC9*CE9*1.6674*POWER(CD9/CE9,-0.768)*DH10),0) -> 0 | DE10: =IF(N10="",VLOOKUP(M10,'HU-MOD-2-Parameters_CROP'!$A$4:$AE$151,24,),N10) -> 0 | DF10: =IF(BG10="",VLOOKUP(M10,'HU-MOD-2-Parameters_CROP'!$A$4:$AE$151,25,),BG10) -> 0 | DG10: =IF(BH10="",VLOOKUP(M10,'HU-MOD-2-Parameters_CROP'!$A$4:$AE$151,26,),BH10) -> 0 | DH10: 1 | DI10: =1-POWER(((G10/10*H10)/(G10/10*H10+F10)),0.5*90) -> 0.42331874 | DJ10: 0.6
A11: Test Farm | B11: Organic Mixed Farm | E11: 10 | F11: 0.4 | G11: 650 | H11: 0.5 | I11: 20 | J11: 2002 | K11: 1 | L11: Catch crop | M11: 1070 | N11: 0 | O11: 0 | P11: Slurry | Q11: 1000 | R11: 15 | S11: 1 | AB11: 10 | AC11: Y | BI11: =E11*(IF(0<BO11-BP11-BQ11-BR11,BO11-BP11-BQ11-BR11,0)-BS11) -> 667.04673 | BJ11: =IF((BV11+BW11)*E11<BT11+BU11,(BV11+BW11)*E11,BT11+BU11) -> 907.71757 | BK11: =BJ11-BI11 -> 240.67085 | BL11: =BK11/E11 -> 24.067085 | BM11: =IF($J12=$J11,BK12+BK11,IF($J10=$J11,"",BK11)) | BN11: =IF($J12=$J11,BL12+BL11,IF($J10=$J11,"",BL11)) | BO11: =1000*(AB11*BY11*CA11+CB11*CC11*CE11+CF11*CG11*CI11+CJ11*CK11*CM11+CN11*CO11*CQ11) -> 85.176471 | BP11: =IF(0<BO11*DE11*DF11-BQ11-BR11,BO11*DE11*DF11-BQ11-BR11,0) -> 0 | BQ11: =IF(BO11*DJ11>CU11+CY11+DA11+DC11+O11*DI11,CU11+CY11+DA11+DC11+O11*DI11,BO11*DJ11) -> 10.005423 | BR11: =I11*DI11 -> 8.4663749 | BS11: =DG11*(1-DI11) -> 0 | BT11: =1000*(CF11*CG11*CH11+CJ11*CK11*CL11+CN11*CO11*CP11) -> 470.58824 | BU11: =1000*(R11*CR11*CS11+V11*CV11*CW11+CZ11*BY10*BZ10+DB11*CC10*CD10) -> 3043.9 | BV11: =1000*(CF11*CG11*CI11+CJ11*CK11*CM11+CN11*CO11*CQ11) -> 25.176471 | BW11: =1000*(IF(R11=0,0,R11*CR11*CT11*(1-1.6674*POWER(CS11/CT11,-0.768)))+IF(V11=0,0,V11*CV11*CX11*(1-1.6674*POWER(CW11/CX11,-0.768)))+IF(CZ11=0,0,CZ11*BY10*CA10*(1-1.6674*POWER(BZ11/CA11,-0.768)))+IF(DB11=0,0,DB11*CC10*CE10*(1-1.6674*POWER(CD10/CE10,-0.768)))) -> 65.595287 | BY11: =IF(AI11="",VLOOKUP($M11,'HU-MOD-2-Parameters_CROP'!$A$4:$AE$151,5,),AI11) -> 0.2 | BZ11: =IF(AJ11="",VLOOKUP($M11,'HU-MOD-2-Parameters_CROP'!$A$4:$AE$151,6,),AJ11) -> 0.46 | CA11: =IF(AK11="",VLOOKUP($M11,'HU-MOD-2-Parameters_CROP'!$A$4:$AE$151,7,),AK11) -> 0.03 | CB11: =IF(AD11="",$AB11*VLOOKUP($M11,'HU-MOD-2-Parameters_CROP'!$A$4:$AE$201,8,),AD11) -> 0 | CC11: =IF(AL11="",VLOOKUP($M11,'HU-MOD-2-Parameters_CROP'!$A$4:$AE$151,9,),AL11) -> 0 | CD11: =IF(AM11="",VLOOKUP($M11,'HU-MOD-2-Parameters_CROP'!$A$4:$AE$151,10,),AM11) -> 0.46 | CE11: =IF(AN11="",VLOOKUP($M11,'HU-MOD-2-Parameters_CROP'!$A$4:$AE$151,11,),AN11) -> 0.03 | CF11: =IF(AF11="",$AB11*VLOOKUP($M11,'HU-MOD-2-Parameters_CROP'!$A$4:$AE$201,12,),AF11) -> 0 | CG11: =IF(AO11="",VLOOKUP($M11,'HU-MOD-2-Parameters_CROP'!$A$4:$AE$151,13,),AO11) -> 0 | CH11: =IF(AP11="",VLOOKUP($M11,'HU-MOD-2-Parameters_CROP'!$A$4:$AE$151,14,),AP11) -> 0 | CI11: =IF(AQ11="",VLOOKUP($M11,'HU-MOD-2-Parameters_CROP'!$A$4:$AE$151,15,),AQ11) -> 0 | CJ11: =IF(AG11="",$AB11*VLOOKUP($M11,'HU-MOD-2-Parameters_CROP'!$A$4:$AE$201,16,),AG11) -> 2.3529412 | CK11: =IF(AR11="",VLOOKUP($M11,'HU-MOD-2-Parameters_CROP'!$A$4:$AE$151,17,),AR11) -> 0 | CL11: =IF(AS11="",VLOOKUP($M11,'HU-MOD-2-Parameters_CROP'!$A$4:$AE$151,18,),AS11) -> 0.46 | CM11: =IF(AT11="",VLOOKUP($M11,'HU-MOD-2-Parameters_CROP'!$A$4:$AE$151,19,),AT11) -> 0.03 | CN11: =IF(AH11="",$AB11*BY11*VLOOKUP($M11,'HU-MOD-2-Parameters_CROP'!$A$4:$AE$201,20,),AH11) -> 1.1764706 | CO11: =IF(AU11="",VLOOKUP($M11,'HU-MOD-2-Parameters_CROP'!$A$4:$AE$151,21,),AU11) -> 1 | CP11: =IF(AV11="",VLOOKUP($M11,'HU-MOD-2-Parameters_CROP'!$A$4:$AE$151,22,),AV11) -> 0.4 | CQ11: =IF(AW11="",VLOOKUP($M11,'HU-MOD-2-Parameters_CROP'!$A$4:$AE$151,23,),AW11) -> 0.0214 | CR11: =IF(AX11="",VLOOKUP($Q11,'HU-MOD-2-Parameters_FTLZ'!$A$4:$I$109,5,),AX11) -> 0.075 | CS11: =IF(AY11="",VLOOKUP($Q11,'HU-MOD-2-Parameters_FTLZ'!$A$4:$I$109,6,),AY11) -> 0.42 | CT11: =IF(AZ11="",VLOOKUP($Q11,'HU-MOD-2-Parameters_FTLZ'!$A$4:$I$109,7,),AZ11) -> 0.053 | CU11: =IF(CR11=0,0,IF(S11=1,1000*R11*CR11*CT11*(1.6674*POWER(CS11/CT11,-0.768))*DI11,1000*R11*CR11*CT11*(1.6674*POWER(CS11/CT11,-0.768))*DH11)) -> 8.5846798 | CV11: =IF(BA11="",VLOOKUP($U11,'HU-MOD-2-Parameters_FTLZ'!$A$4:$I$109,5,),BA11) -> 0 | CW11: =IF(BB11="",VLOOKUP($U11,'HU-MOD-2-Parameters_FTLZ'!$A$4:$I$109,6,),BB11) -> 0 | CX11: =IF(BC11="",VLOOKUP($U11,'HU-MOD-2-Parameters_FTLZ'!$A$4:$I$109,7,),BC11) -> 0 | CY11: =IF(CV11=0,0,IF(W11=1,1000*V11*CV11*CX11*(1.6674*POWER(CW11/CX11,-0.768))*DI11,1000*V11*CV11*CX11*(1.6674*POWER(CW11/CX11,-0.768))*DH11)) -> 0 | CZ11: =IF(X11="",IF(AC10="Y",AB10,0),X11) -> 0 | DA11: =IF(AC10="Y",IF(Y11=1,1000*CZ11*BY10*CA10*1.6674*POWER(BZ10/CA10,-0.768)*DI11,1000*CZ11*BY10*CA10*1.6674*POWER(BZ10/CA10,-0.768)*DH11),0) -> 0 | DB11: =IF(Z11="",IF(AE10="Y",CB10,0),Z11) -> 6.5 | DC11: =IF(AE10="Y",IF(AB11=1,1000*DB11*CC10*CE10*1.6674*POWER(CD10/CE10,-0.768)*DI11,1000*DB11*CC10*CE10*1.6674*POWER(CD10/CE10,-0.768)*DH11),0) -> 1.4207432 | DE11: =IF(N11="",VLOOKUP(M11,'HU-MOD-2-Parameters_CROP'!$A$4:$AE$151,24,),N11) -> 0 | DF11: =IF(BG11="",VLOOKUP(M11,'HU-MOD-2-Parameters_CROP'!$A$4:$AE$151,25,),BG11) -> 0.85 | DG11: =IF(BH11="",VLOOKUP(M11,'HU-MOD-2-Parameters_CROP'!$A$4:$AE$151,26,),BH11) -> 0 | DH11: 1 | DI11: =1-POWER(((G11/10*H11)/(G11/10*H11+F11)),0.5*90) -> 0.42331874 | DJ11: 0.6
A12: Test Farm | B12: Organic Mixed Farm | E12: 10 | F12: 0.4 | G12: 650 | H12: 0.5 | I12: 20 | J12: 2003 | K12: 1 | L12: Potatos | M12: 1034 | N12: 0 | O12: 0 | AB12: 26 | AC12: N | BI12: =E12*(IF(0<BO12-BP12-BQ12-BR12,BO12-BP12-BQ12-BR12,0)-BS12) -> 1359.0266 | BJ12: =IF((BV12+BW12)*E12<BT12+BU12,(BV12+BW12)*E12,BT12+BU12) -> 976.07153 | BK12: =BJ12-BI12 -> -382.95512 | BL12: =BK12/E12 -> -38.295512 | BM12: =IF($J13=$J12,BK13+BK12,IF($J11=$J12,"",BK12)) -> -382.95512 | BN12: =IF($J13=$J12,BL13+BL12,IF($J11=$J12,"",BL12)) -> -38.295512 | BO12: =1000*(AB12*BY12*CA12+CB12*CC12*CE12+CF12*CG12*CI12+CJ12*CK12*CM12+CN12*CO12*CQ12) -> 133.59378 | BP12: =IF(0<BO12*DE12*DF12-BQ12-BR12,BO12*DE12*DF12-BQ12-BR12,0) -> 0 | BQ12: =IF(BO12*DJ12>CU12+CY12+DA12+DC12+O12*DI12,CU12+CY12+DA12+DC12+O12*DI12,BO12*DJ12) -> 12.291989 | BR12: =I12*DI12 -> 8.4663749 | BS12: =DG12*(1-DI12) -> -23.06725 | BT12: =1000*(CF12*CG12*CH12+CJ12*CK12*CL12+CN12*CO12*CP12) -> 1479.1111 | BU12: =1000*(R12*CR12*CS12+V12*CV12*CW12+CZ12*BY11*BZ11+DB12*CC11*CD11) -> 920 | BV12: =1000*(CF12*CG12*CI12+CJ12*CK12*CM12+CN12*CO12*CQ12) -> 45.505778 | BW12: =1000*(IF(R12=0,0,R12*CR12*CT12*(1-1.6674*POWER(CS12/CT12,-0.768)))+IF(V12=0,0,V12*CV12*CX12*(1-1.6674*POWER(CW12/CX12,-0.768)))+IF(CZ12=0,0,CZ12*BY11*CA11*(1-1.6674*POWER(BZ12/CA12,-0.768)))+IF(DB12=0,0,DB12*CC11*CE11*(1-1.6674*POWER(CD11/CE11,-0.768)))) -> 52.101375 | BY12: =IF(AI12="",VLOOKUP($M12,'HU-MOD-2-Parameters_CROP'!$A$4:$AE$151,5,),AI12) -> 0.22 | BZ12: =IF(AJ12="",VLOOKUP($M12,'HU-MOD-2-Parameters_CROP'!$A$4:$AE$151,6,),AJ12) -> 0.42 | CA12: =IF(AK12="",VLOOKUP($M12,'HU-MOD-2-Parameters_CROP'!$A$4:$AE$151,7,),AK12) -> 0.0154 | CB12: =IF(AD12="",$AB12*VLOOKUP($M12,'HU-MOD-2-Parameters_CROP'!$A$4:$AE$201,8,),AD12) -> 0 | CC12: =IF(AL12="",VLOOKUP($M12,'HU-MOD-2-Parameters_CROP'!$A$4:$AE$151,9,),AL12) -> 0.4 | CD12: =IF(AM12="",VLOOKUP($M12,'HU-MOD-2-Parameters_CROP'!$A$4:$AE$151,10,),AM12) -> 0.4 | CE12: =IF(AN12="",VLOOKUP($M12,'HU-MOD-2-Parameters_CROP'!$A$4:$AE$151,11,),AN12) -> 0.0099 | CF12: =IF(AF12="",$AB12*VLOOKUP($M12,'HU-MOD-2-Parameters_CROP'!$A$4:$AE$201,12,),AF12) -> 0 | CG12: =IF(AO12="",VLOOKUP($M12,'HU-MOD-2-Parameters_CROP'!$A$4:$AE$151,13,),AO12) -> 0 | CH12: =IF(AP12="",VLOOKUP($M12,'HU-MOD-2-Parameters_CROP'!$A$4:$AE$151,14,),AP12) -> 0 | CI12: =IF(AQ12="",VLOOKUP($M12,'HU-MOD-2-Parameters_CROP'!$A$4:$AE$151,15,),AQ12) -> 0 | CJ12: =IF(AG12="",$AB12*VLOOKUP($M12,'HU-MOD-2-Parameters_CROP'!$A$4:$AE$201,16,),AG12) -> 7.8 | CK12: =IF(AR12="",VLOOKUP($M12,'HU-MOD-2-Parameters_CROP'!$A$4:$AE$151,17,),AR12) -> 0.4 | CL12: =IF(AS12="",VLOOKUP($M12,'HU-MOD-2-Parameters_CROP'!$A$4:$AE$151,18,),AS12) -> 0.4 | CM12: =IF(AT12="",VLOOKUP($M12,'HU-MOD-2-Parameters_CROP'!$A$4:$AE$151,19,),AT12) -> 0.0099 | CN12: =IF(AH12="",$AB12*BY12*VLOOKUP($M12,'HU-MOD-2-Parameters_CROP'!$A$4:$AE$201,20,),AH12) -> 0.57777778 | CO12: =IF(AU12="",VLOOKUP($M12,'HU-MOD-2-Parameters_CROP'!$A$4:$AE$151,21,),AU12) -> 1 | CP12: =IF(AV12="",VLOOKUP($M12,'HU-MOD-2-Parameters_CROP'!$A$4:$AE$151,22,),AV12) -> 0.4 | CQ12: =IF(AW12="",VLOOKUP($M12,'HU-MOD-2-Parameters_CROP'!$A$4:$AE$151,23,),AW12) -> 0.0253 | CR12: =IF(AX12="",VLOOKUP($Q12,'HU-MOD-2-Parameters_FTLZ'!$A$4:$I$109,5,),AX12) -> 0 | CS12: =IF(AY12="",VLOOKUP($Q12,'HU-MOD-2-Parameters_FTLZ'!$A$4:$I$109,6,),AY12) -> 0 | CT12: =IF(AZ12="",VLOOKUP($Q12,'HU-MOD-2-Parameters_FTLZ'!$A$4:$I$109,7,),AZ12) -> 0 | CU12: =IF(CR12=0,0,IF(S12=1,1000*R12*CR12*CT12*(1.6674*POWER(CS12/CT12,-0.768))*DI12,1000*R12*CR12*CT12*(1.6674*POWER(CS12/CT12,-0.768))*DH12)) -> 0 | CV12: =IF(BA12="",VLOOKUP($U12,'HU-MOD-2-Parameters_FTLZ'!$A$4:$I$109,5,),BA12) -> 0 | CW12: =IF(BB12="",VLOOKUP($U12,'HU-MOD-2-Parameters_FTLZ'!$A$4:$I$109,6,),BB12) -> 0 | CX12: =IF(BC12="",VLOOKUP($U12,'HU-MOD-2-Parameters_FTLZ'!$A$4:$I$109,7,),BC12) -> 0 | CY12: =IF(CV12=0,0,IF(W12=1,1000*V12*CV12*CX12*(1.6674*POWER(CW12/CX12,-0.768))*DI12,1000*V12*CV12*CX12*(1.6674*POWER(CW12/CX12,-0.768))*DH12)) -> 0 | CZ12: =IF(X12="",IF(AC11="Y",AB11,0),X12) -> 10 | DA12: =IF(AC11="Y",IF(Y12=1,1000*CZ12*BY11*CA11*1.6674*POWER(BZ11/CA11,-0.768)*DI12,1000*CZ12*BY11*CA11*1.6674*POWER(BZ11/CA11,-0.768)*DH12),0) -> 12.291989 | DB12: =IF(Z12="",IF(AE11="Y",CB11,0),Z12) -> 0 | DC12: =IF(AE11="Y",IF(AB12=1,1000*DB12*CC11*CE11*1.6674*POWER(CD11/CE11,-0.768)*DI12,1000*DB12*CC11*CE11*1.6674*POWER(CD11/CE11,-0.768)*DH12),0) -> 0 | DE12: =IF(N12="",VLOOKUP(M12,'HU-MOD-2-Parameters_CROP'!$A$4:$AE$151,24,),N12) -> 0 | DF12: =IF(BG12="",VLOOKUP(M12,'HU-MOD-2-Parameters_CROP'!$A$4:$AE$151,25,),BG12) -> 0 | DG12: =IF(BH12="",VLOOKUP(M12,'HU-MOD-2-Parameters_CROP'!$A$4:$AE$151,26,),BH12) -> -40 | DH12: 1 | DI12: =1-POWER(((G12/10*H12)/(G12/10*H12+F12)),0.5*90) -> 0.42331874 | DJ12: 0.6

Sheet HU-MOD-2-Parameters_CROP
E1: DMMP | F1: MPC | G1: MPN | H1: RATIO_SPMP | I1: DMSP | J1: SPC | K1: SPN | L1: RATIO_LITMP | M1: LITDM | N1: LITC | O1: LITN | P1: RATIO_STBMP | Q1: STBDM | R1: STBC | S1: STBN | T1: RATIO_ROSH | U1: RTSDM | V1: RTSC | W1: RTSN | X1: Leg_share | Y1: NDFA | Z1: NYRN | AA1: NAV | AB1: LUFA-U | AC1: LUFA-O | AD1: LUFA-ÖKO | AE1: Ertrag_Default | AF1: LUFA-SUP | AG1: LUFA-SUP_neu
A2: 1 | B2: 2 | C2: 3 | D2: 4 | E2: 5 | F2: 6 | G2: 7 | H2: 8 | I2: 9 | J2: 10 | K2: 11 | L2: 12 | M2: 13 | N2: 14 | O2: 15 | P2: 16 | Q2: 17 | R2: 18 | S2: 19 | T2: 20 | U2: 21 | V2: 22 | W2: 23 | X2: 24 | Y2: 25 | Z2: 26 | AA2: 27 | AB2: 28 | AC2: 29 | AD2: 30 | AE2: 31 | AF2: 32 | AG2: 33
A3: CROP-ID | B3: ITEM_IX-humult | C3: Name GER | D3: Name ENG | E3: Faktor | G3: Faktor | I3: Faktor | K3: Faktor | AE3: dt FM/ha
A4: 0 | B4: 0 | C4: Dummy | D4: Dummy | E4: 0 | F4: 0 | G4: 0 | H4: 0 | I4: 0 | J4: 0 | K4: 0 | L4: 0 | M4: 0 | N4: 0 | O4: 0 | P4: 0 | Q4: 0 | R4: 0 | S4: 0 | T4: 0 | U4: 0 | V4: 0 | W4: 0 | X4: 0 | Y4: 0 | AA4: 0 | AB4: 0 | AC4: 0 | AD4: 0 | AE4: 0
A5: 1001 | B5: 38 | C5: Winterweizen | D5: Winter wheat | E5: 0.86 | F5: 0.445 | G5: 0.0198 | H5: 1 | I5: 0.86 | J5: 0.46 | K5: 0.00495 | L5: 0 | M5: 0 | N5: 0 | O5: 0 | P5: 0.2 | Q5: 0.86 | R5: 0.46 | S5: 0.00495 | T5: 0.5 | U5: 1 | V5: 0.4 | W5: 0.0088 | X5: 0 | Y5: 0 | Z5: 0 | AA5: 0.25 | AB5: 280 | AC5: 400 | AD5: 520 | AE5: 45 | AF5: 100 | AG5: ='HU-MOD-2-Parameters_FTLZ'!J$38 -> 30.04736
A6: 1002 | B6: 33 | C6: Sommerweizen | D6: Summer wheat | E6: 0.86 | F6: 0.445 | G6: 0.018 | H6: 1.2 | I6: 0.86 | J6: 0.46 | K6: 0.0045 | L6: 0 | M6: 0 | N6: 0 | O6: 0 | P6: 0.32 | Q6: 0.86 | R6: 0.46 | S6: 0.0045 | T6: 0.8 | U6: 1 | V6: 0.4 | W6: 0.008 | X6: 0 | Y6: 0 | Z6: -40 | AA6: 0.25 | AB6: 280 | AC6: 400 | AD6: 520 | AE6: 35 | AF6: 100 | AG6: ='HU-MOD-2-Parameters_FTLZ'!J$38 -> 30.04736
A7: 1003 | B7: 49 | C7: Winterkorn (Spelz, Dinkel) | D7: Winter Spelt | E7: 0.86 | F7: 0.445 | G7: 0.0176 | H7: 1.2 | I7: 0.86 | J7: 0.46 | K7: 0.0043 | L7: 0 | M7: 0 | N7: 0 | O7: 0 | P7: 0.32 | Q7: 0.86 | R7: 0.46 | S7: 0.0043 | T7: 0.8 | U7: 1 | V7: 0.4 | W7: 0.008 | X7: 0 | Y7: 0 | Z7: 0 | AA7: 0.25 | AB7: 280 | AC7: 400 | AD7: 520 | AE7: 40 | AF7: 100 | AG7: ='HU-MOD-2-Parameters_FTLZ'!J$38 -> 30.04736
A8: 1004 | B8: 37 | C8: Winterroggen | D8: Winter rye | E8: 0.86 | F8: 0.445 | G8: 0.0198 | H8: 1.3 | I8: 0.86 | J8: 0.46 | K8: 0.00495 | L8: 0 | M8: 0 | N8: 0 | O8: 0 | P8: 0.26190476 | Q8: 0.86 | R8: 0.46 | S8: 0.00495 | T8: 0.73333333 | U8: 1 | V8: 0.4 | W8: 0.0088 | X8: 0 | Y8: 0 | Z8: 0 | AA8: 0.25 | AB8: 280 | AC8: 400 | AD8: 520 | AE8: 40 | AF8: 100 | AG8: ='HU-MOD-2-Parameters_FTLZ'!J$38 -> 30.04736
A9: 1005 | B9: 50 | C9: Sommerroggen | D9: Summer rye | E9: 0.86 | F9: 0.445 | G9: 0.017 | H9: 1.4 | I9: 0.86 | J9: 0.46 | K9: 0.0045 | L9: 0 | M9: 0 | N9: 0 | O9: 0 | P9: 0.26260504 | Q9: 0.86 | R9: 0.46 | S9: 0.0045 | T9: 0.73529412 | U9: 1 | V9: 0.4 | W9: 0.008 | X9: 0 | Y9: 0 | Z9: -40 | AA9: 0.25 | AB9: 280 | AC9: 400 | AD9: 520 | AE9: 35 | AF9: 100 | AG9: ='HU-MOD-2-Parameters_FTLZ'!J$38 -> 30.04736
A10: 1006 | B10: 51 | C10: Wintergerste | D10: Winter barley | E10: 0.86 | F10: 0.445 | G10: 0.018 | H10: 1 | I10: 0.86 | J10: 0.46 | K10: 0.0045 | L10: 0 | M10: 0 | N10: 0 | O10: 0 | P10: 0.22857143 | Q10: 0.86 | R10: 0.46 | S10: 0.0045 | T10: 0.57142857 | U10: 1 | V10: 0.4 | W10: 0.008 | X10: 0 | Y10: 0 | Z10: 0 | AA10: 0.25 | AB10: 280 | AC10: 400 | AD10: 520 | AE10: 40 | AF10: 100 | AG10: ='HU-MOD-2-Parameters_FTLZ'!J$38 -> 30.04736
A11: 1007 | B11: 31 | C11: Sommergerste | D11: Summer barley | E11: 0.86 | F11: 0.445 | G11: 0.018 | H11: 1 | I11: 0.86 | J11: 0.46 | K11: 0.0045 | L11: 0 | M11: 0 | N11: 0 | O11: 0 | P11: 0.29545455 | Q11: 0.86 | R11: 0.46 | S11: 0.0045 | T11: 0.65 | U11: 1 | V11: 0.4 | W11: 0.008 | X11: 0 | Y11: 0 | Z11: -40 | AA11: 0.25 | AB11: 280 | AC11: 400 | AD11: 520 | AE11: 35 | AF11: 100 | AG11: ='HU-MOD-2-Parameters_FTLZ'!J$38 -> 30.04736
